025-05-16 16:18:14,073 - werkzeug - INFO - [31m[1mWARNING: This is a development server. Do not use it in a production deployment. Use a production WSGI server instead.[0m
 * Running on all addresses (0.0.0.0)
 * Running on http://127.0.0.1:5000
 * Running on http://192.168.31.105:5000
2025-05-16 16:18:14,074 - werkzeug - INFO - [33mPress CTRL+C to quit[0m
2025-05-16 16:27:45,777 - werkzeug - INFO - [31m[1mWARNING: This is a development server. Do not use it in a production deployment. Use a production WSGI server instead.[0m
 * Running on all addresses (0.0.0.0)
 * Running on http://127.0.0.1:5000
 * Running on http://192.168.31.105:5000
2025-05-16 16:27:45,801 - werkzeug - INFO - [33mPress CTRL+C to quit[0m
2025-05-16 16:39:44,891 - werkzeug - INFO - [31m[1mWARNING: This is a development server. Do not use it in a production deployment. Use a production WSGI server instead.[0m
 * Running on all addresses (0.0.0.0)
 * Running on http://127.0.0.1:5000
 * Running on http://192.168.31.105:5000
2025-05-16 16:39:44,891 - werkzeug - INFO - [33mPress CTRL+C to quit[0m
2025-05-16 17:02:16,320 - werkzeug - INFO - [31m[1mWARNING: This is a development server. Do not use it in a production deployment. Use a production WSGI server instead.[0m
 * Running on all addresses (0.0.0.0)
 * Running on http://127.0.0.1:5000
 * Running on http://192.168.31.105:5000
2025-05-16 17:02:16,320 - werkzeug - INFO - [33mPress CTRL+C to quit[0m
2025-05-16 17:08:49,964 - werkzeug - INFO - [31m[1mWARNING: This is a development server. Do not use it in a production deployment. Use a production WSGI server instead.[0m
 * Running on all addresses (0.0.0.0)
 * Running on http://127.0.0.1:5000
 * Running on http://192.168.31.105:5000
2025-05-16 17:08:49,979 - werkzeug - INFO - [33mPress CTRL+C to quit[0m
2025-05-16 17:26:37,077 - werkzeug - INFO - [31m[1mWARNING: This is a development server. Do not use it in a production deployment. Use a production WSGI server instead.[0m
 * Running on all addresses (0.0.0.0)
 * Running on http://127.0.0.1:5000
 * Running on http://192.168.31.105:5000
2025-05-16 17:26:37,078 - werkzeug - INFO - [33mPress CTRL+C to quit[0m
2025-05-16 17:28:18,232 - werkzeug - INFO - [31m[1mWARNING: This is a development server. Do not use it in a production deployment. Use a production WSGI server instead.[0m
 * Running on all addresses (0.0.0.0)
 * Running on http://127.0.0.1:5000
 * Running on http://192.168.31.105:5000
2025-05-16 17:28:18,232 - werkzeug - INFO - [33mPress CTRL+C to quit[0m
2025-05-16 18:36:03,208 - werkzeug - INFO - [31m[1mWARNING: This is a development server. Do not use it in a production deployment. Use a production WSGI server instead.[0m
 * Running on all addresses (0.0.0.0)
 * Running on http://127.0.0.1:5000
 * Running on http://192.168.31.105:5000
2025-05-16 18:36:03,209 - werkzeug - INFO - [33mPress CTRL+C to quit[0m
2025-05-16 20:56:18,660 - werkzeug - INFO - [31m[1mWARNING: This is a development server. Do not use it in a production deployment. Use a production WSGI server instead.[0m
 * Running on all addresses (0.0.0.0)
 * Running on http://127.0.0.1:5000
 * Running on http://192.168.31.105:5000
2025-05-16 20:56:18,670 - werkzeug - INFO - [33mPress CTRL+C to quit[0m
2025-05-17 09:23:56,408 - telegram.ext.Application - ERROR - No error handlers are registered, logging exception.
Traceback (most recent call last):
  File "D:\Programming\Python\Supp0rtBot\.venv\Lib\site-packages\httpx\_transports\default.py", line 101, in map_httpcore_exceptions
    yield
  File "D:\Programming\Python\Supp0rtBot\.venv\Lib\site-packages\httpx\_transports\default.py", line 394, in handle_async_request
    resp = await self._pool.handle_async_request(req)
           ^^^^^^^^^^^^^^^^^^^^^^^^^^^^^^^^^^^^^^^^^^
  File "D:\Programming\Python\Supp0rtBot\.venv\Lib\site-packages\httpcore\_async\connection_pool.py", line 256, in handle_async_request
    raise exc from None
  File "D:\Programming\Python\Supp0rtBot\.venv\Lib\site-packages\httpcore\_async\connection_pool.py", line 236, in handle_async_request
    response = await connection.handle_async_request(
               ^^^^^^^^^^^^^^^^^^^^^^^^^^^^^^^^^^^^^^
  File "D:\Programming\Python\Supp0rtBot\.venv\Lib\site-packages\httpcore\_async\connection.py", line 101, in handle_async_request
    raise exc
  File "D:\Programming\Python\Supp0rtBot\.venv\Lib\site-packages\httpcore\_async\connection.py", line 78, in handle_async_request
    stream = await self._connect(request)
             ^^^^^^^^^^^^^^^^^^^^^^^^^^^^
  File "D:\Programming\Python\Supp0rtBot\.venv\Lib\site-packages\httpcore\_async\connection.py", line 124, in _connect
    stream = await self._network_backend.connect_tcp(**kwargs)
             ^^^^^^^^^^^^^^^^^^^^^^^^^^^^^^^^^^^^^^^^^^^^^^^^^
  File "D:\Programming\Python\Supp0rtBot\.venv\Lib\site-packages\httpcore\_backends\auto.py", line 31, in connect_tcp
    return await self._backend.connect_tcp(
           ^^^^^^^^^^^^^^^^^^^^^^^^^^^^^^^^
  File "D:\Programming\Python\Supp0rtBot\.venv\Lib\site-packages\httpcore\_backends\anyio.py", line 113, in connect_tcp
    with map_exceptions(exc_map):
  File "C:\Users\38066\AppData\Local\Programs\Python\Python312\Lib\contextlib.py", line 158, in __exit__
    self.gen.throw(value)
  File "D:\Programming\Python\Supp0rtBot\.venv\Lib\site-packages\httpcore\_exceptions.py", line 14, in map_exceptions
    raise to_exc(exc) from exc
httpcore.ConnectError: [Errno 11001] getaddrinfo failed

The above exception was the direct cause of the following exception:

Traceback (most recent call last):
  File "D:\Programming\Python\Supp0rtBot\.venv\Lib\site-packages\telegram\request\_httpxrequest.py", line 293, in do_request
    res = await self._client.request(
          ^^^^^^^^^^^^^^^^^^^^^^^^^^^
  File "D:\Programming\Python\Supp0rtBot\.venv\Lib\site-packages\httpx\_client.py", line 1540, in request
    return await self.send(request, auth=auth, follow_redirects=follow_redirects)
           ^^^^^^^^^^^^^^^^^^^^^^^^^^^^^^^^^^^^^^^^^^^^^^^^^^^^^^^^^^^^^^^^^^^^^^
  File "D:\Programming\Python\Supp0rtBot\.venv\Lib\site-packages\httpx\_client.py", line 1629, in send
    response = await self._send_handling_auth(
               ^^^^^^^^^^^^^^^^^^^^^^^^^^^^^^^
  File "D:\Programming\Python\Supp0rtBot\.venv\Lib\site-packages\httpx\_client.py", line 1657, in _send_handling_auth
    response = await self._send_handling_redirects(
               ^^^^^^^^^^^^^^^^^^^^^^^^^^^^^^^^^^^^
  File "D:\Programming\Python\Supp0rtBot\.venv\Lib\site-packages\httpx\_client.py", line 1694, in _send_handling_redirects
    response = await self._send_single_request(request)
               ^^^^^^^^^^^^^^^^^^^^^^^^^^^^^^^^^^^^^^^^
  File "D:\Programming\Python\Supp0rtBot\.venv\Lib\site-packages\httpx\_client.py", line 1730, in _send_single_request
    response = await transport.handle_async_request(request)
               ^^^^^^^^^^^^^^^^^^^^^^^^^^^^^^^^^^^^^^^^^^^^^
  File "D:\Programming\Python\Supp0rtBot\.venv\Lib\site-packages\httpx\_transports\default.py", line 393, in handle_async_request
    with map_httpcore_exceptions():
  File "C:\Users\38066\AppData\Local\Programs\Python\Python312\Lib\contextlib.py", line 158, in __exit__
    self.gen.throw(value)
  File "D:\Programming\Python\Supp0rtBot\.venv\Lib\site-packages\httpx\_transports\default.py", line 118, in map_httpcore_exceptions
    raise mapped_exc(message) from exc
httpx.ConnectError: [Errno 11001] getaddrinfo failed

The above exception was the direct cause of the following exception:

Traceback (most recent call last):
  File "D:\Programming\Python\Supp0rtBot\.venv\Lib\site-packages\telegram\ext\_updater.py", line 750, in _network_loop_retry
    if not await do_action():
           ^^^^^^^^^^^^^^^^^
  File "D:\Programming\Python\Supp0rtBot\.venv\Lib\site-packages\telegram\ext\_updater.py", line 744, in do_action
    return action_cb_task.result()
           ^^^^^^^^^^^^^^^^^^^^^^^
  File "C:\Users\38066\AppData\Local\Programs\Python\Python312\Lib\asyncio\futures.py", line 203, in result
    raise self._exception.with_traceback(self._exception_tb)
  File "C:\Users\38066\AppData\Local\Programs\Python\Python312\Lib\asyncio\tasks.py", line 316, in __step_run_and_handle_result
    result = coro.throw(exc)
             ^^^^^^^^^^^^^^^
  File "D:\Programming\Python\Supp0rtBot\.venv\Lib\site-packages\telegram\ext\_updater.py", line 371, in polling_action_cb
    updates = await self.bot.get_updates(
              ^^^^^^^^^^^^^^^^^^^^^^^^^^^
  File "D:\Programming\Python\Supp0rtBot\.venv\Lib\site-packages\telegram\ext\_extbot.py", line 650, in get_updates
    updates = await super().get_updates(
              ^^^^^^^^^^^^^^^^^^^^^^^^^^
  File "D:\Programming\Python\Supp0rtBot\.venv\Lib\site-packages\telegram\_bot.py", line 4480, in get_updates
    await self._post(
  File "D:\Programming\Python\Supp0rtBot\.venv\Lib\site-packages\telegram\_bot.py", line 619, in _post
    return await self._do_post(
           ^^^^^^^^^^^^^^^^^^^^
  File "D:\Programming\Python\Supp0rtBot\.venv\Lib\site-packages\telegram\ext\_extbot.py", line 354, in _do_post
    return await super()._do_post(
           ^^^^^^^^^^^^^^^^^^^^^^^
  File "D:\Programming\Python\Supp0rtBot\.venv\Lib\site-packages\telegram\_bot.py", line 648, in _do_post
    result = await request.post(
             ^^^^^^^^^^^^^^^^^^^
  File "D:\Programming\Python\Supp0rtBot\.venv\Lib\site-packages\telegram\request\_baserequest.py", line 202, in post
    result = await self._request_wrapper(
             ^^^^^^^^^^^^^^^^^^^^^^^^^^^^
  File "D:\Programming\Python\Supp0rtBot\.venv\Lib\site-packages\telegram\request\_baserequest.py", line 334, in _request_wrapper
    code, payload = await self.do_request(
                    ^^^^^^^^^^^^^^^^^^^^^^
  File "D:\Programming\Python\Supp0rtBot\.venv\Lib\site-packages\telegram\request\_httpxrequest.py", line 317, in do_request
    raise NetworkError(f"httpx.{err.__class__.__name__}: {err}") from err
telegram.error.NetworkError: httpx.ConnectError: [Errno 11001] getaddrinfo failed
2025-05-17 09:24:00,232 - telegram.ext.Application - ERROR - No error handlers are registered, logging exception.
Traceback (most recent call last):
  File "D:\Programming\Python\Supp0rtBot\.venv\Lib\site-packages\httpx\_transports\default.py", line 101, in map_httpcore_exceptions
    yield
  File "D:\Programming\Python\Supp0rtBot\.venv\Lib\site-packages\httpx\_transports\default.py", line 394, in handle_async_request
    resp = await self._pool.handle_async_request(req)
           ^^^^^^^^^^^^^^^^^^^^^^^^^^^^^^^^^^^^^^^^^^
  File "D:\Programming\Python\Supp0rtBot\.venv\Lib\site-packages\httpcore\_async\connection_pool.py", line 256, in handle_async_request
    raise exc from None
  File "D:\Programming\Python\Supp0rtBot\.venv\Lib\site-packages\httpcore\_async\connection_pool.py", line 236, in handle_async_request
    response = await connection.handle_async_request(
               ^^^^^^^^^^^^^^^^^^^^^^^^^^^^^^^^^^^^^^
  File "D:\Programming\Python\Supp0rtBot\.venv\Lib\site-packages\httpcore\_async\connection.py", line 101, in handle_async_request
    raise exc
  File "D:\Programming\Python\Supp0rtBot\.venv\Lib\site-packages\httpcore\_async\connection.py", line 78, in handle_async_request
    stream = await self._connect(request)
             ^^^^^^^^^^^^^^^^^^^^^^^^^^^^
  File "D:\Programming\Python\Supp0rtBot\.venv\Lib\site-packages\httpcore\_async\connection.py", line 124, in _connect
    stream = await self._network_backend.connect_tcp(**kwargs)
             ^^^^^^^^^^^^^^^^^^^^^^^^^^^^^^^^^^^^^^^^^^^^^^^^^
  File "D:\Programming\Python\Supp0rtBot\.venv\Lib\site-packages\httpcore\_backends\auto.py", line 31, in connect_tcp
    return await self._backend.connect_tcp(
           ^^^^^^^^^^^^^^^^^^^^^^^^^^^^^^^^
  File "D:\Programming\Python\Supp0rtBot\.venv\Lib\site-packages\httpcore\_backends\anyio.py", line 113, in connect_tcp
    with map_exceptions(exc_map):
  File "C:\Users\38066\AppData\Local\Programs\Python\Python312\Lib\contextlib.py", line 158, in __exit__
    self.gen.throw(value)
  File "D:\Programming\Python\Supp0rtBot\.venv\Lib\site-packages\httpcore\_exceptions.py", line 14, in map_exceptions
    raise to_exc(exc) from exc
httpcore.ConnectError: [Errno 11001] getaddrinfo failed

The above exception was the direct cause of the following exception:

Traceback (most recent call last):
  File "D:\Programming\Python\Supp0rtBot\.venv\Lib\site-packages\telegram\request\_httpxrequest.py", line 293, in do_request
    res = await self._client.request(
          ^^^^^^^^^^^^^^^^^^^^^^^^^^^
  File "D:\Programming\Python\Supp0rtBot\.venv\Lib\site-packages\httpx\_client.py", line 1540, in request
    return await self.send(request, auth=auth, follow_redirects=follow_redirects)
           ^^^^^^^^^^^^^^^^^^^^^^^^^^^^^^^^^^^^^^^^^^^^^^^^^^^^^^^^^^^^^^^^^^^^^^
  File "D:\Programming\Python\Supp0rtBot\.venv\Lib\site-packages\httpx\_client.py", line 1629, in send
    response = await self._send_handling_auth(
               ^^^^^^^^^^^^^^^^^^^^^^^^^^^^^^^
  File "D:\Programming\Python\Supp0rtBot\.venv\Lib\site-packages\httpx\_client.py", line 1657, in _send_handling_auth
    response = await self._send_handling_redirects(
               ^^^^^^^^^^^^^^^^^^^^^^^^^^^^^^^^^^^^
  File "D:\Programming\Python\Supp0rtBot\.venv\Lib\site-packages\httpx\_client.py", line 1694, in _send_handling_redirects
    response = await self._send_single_request(request)
               ^^^^^^^^^^^^^^^^^^^^^^^^^^^^^^^^^^^^^^^^
  File "D:\Programming\Python\Supp0rtBot\.venv\Lib\site-packages\httpx\_client.py", line 1730, in _send_single_request
    response = await transport.handle_async_request(request)
               ^^^^^^^^^^^^^^^^^^^^^^^^^^^^^^^^^^^^^^^^^^^^^
  File "D:\Programming\Python\Supp0rtBot\.venv\Lib\site-packages\httpx\_transports\default.py", line 393, in handle_async_request
    with map_httpcore_exceptions():
  File "C:\Users\38066\AppData\Local\Programs\Python\Python312\Lib\contextlib.py", line 158, in __exit__
    self.gen.throw(value)
  File "D:\Programming\Python\Supp0rtBot\.venv\Lib\site-packages\httpx\_transports\default.py", line 118, in map_httpcore_exceptions
    raise mapped_exc(message) from exc
httpx.ConnectError: [Errno 11001] getaddrinfo failed

The above exception was the direct cause of the following exception:

Traceback (most recent call last):
  File "D:\Programming\Python\Supp0rtBot\.venv\Lib\site-packages\telegram\ext\_updater.py", line 750, in _network_loop_retry
    if not await do_action():
           ^^^^^^^^^^^^^^^^^
  File "D:\Programming\Python\Supp0rtBot\.venv\Lib\site-packages\telegram\ext\_updater.py", line 744, in do_action
    return action_cb_task.result()
           ^^^^^^^^^^^^^^^^^^^^^^^
  File "C:\Users\38066\AppData\Local\Programs\Python\Python312\Lib\asyncio\futures.py", line 203, in result
    raise self._exception.with_traceback(self._exception_tb)
  File "C:\Users\38066\AppData\Local\Programs\Python\Python312\Lib\asyncio\tasks.py", line 316, in __step_run_and_handle_result
    result = coro.throw(exc)
             ^^^^^^^^^^^^^^^
  File "D:\Programming\Python\Supp0rtBot\.venv\Lib\site-packages\telegram\ext\_updater.py", line 371, in polling_action_cb
    updates = await self.bot.get_updates(
              ^^^^^^^^^^^^^^^^^^^^^^^^^^^
  File "D:\Programming\Python\Supp0rtBot\.venv\Lib\site-packages\telegram\ext\_extbot.py", line 650, in get_updates
    updates = await super().get_updates(
              ^^^^^^^^^^^^^^^^^^^^^^^^^^
  File "D:\Programming\Python\Supp0rtBot\.venv\Lib\site-packages\telegram\_bot.py", line 4480, in get_updates
    await self._post(
  File "D:\Programming\Python\Supp0rtBot\.venv\Lib\site-packages\telegram\_bot.py", line 619, in _post
    return await self._do_post(
           ^^^^^^^^^^^^^^^^^^^^
  File "D:\Programming\Python\Supp0rtBot\.venv\Lib\site-packages\telegram\ext\_extbot.py", line 354, in _do_post
    return await super()._do_post(
           ^^^^^^^^^^^^^^^^^^^^^^^
  File "D:\Programming\Python\Supp0rtBot\.venv\Lib\site-packages\telegram\_bot.py", line 648, in _do_post
    result = await request.post(
             ^^^^^^^^^^^^^^^^^^^
  File "D:\Programming\Python\Supp0rtBot\.venv\Lib\site-packages\telegram\request\_baserequest.py", line 202, in post
    result = await self._request_wrapper(
             ^^^^^^^^^^^^^^^^^^^^^^^^^^^^
  File "D:\Programming\Python\Supp0rtBot\.venv\Lib\site-packages\telegram\request\_baserequest.py", line 334, in _request_wrapper
    code, payload = await self.do_request(
                    ^^^^^^^^^^^^^^^^^^^^^^
  File "D:\Programming\Python\Supp0rtBot\.venv\Lib\site-packages\telegram\request\_httpxrequest.py", line 317, in do_request
    raise NetworkError(f"httpx.{err.__class__.__name__}: {err}") from err
telegram.error.NetworkError: httpx.ConnectError: [Errno 11001] getaddrinfo failed
2025-05-17 09:24:02,021 - telegram.ext.Application - ERROR - No error handlers are registered, logging exception.
Traceback (most recent call last):
  File "D:\Programming\Python\Supp0rtBot\.venv\Lib\site-packages\httpx\_transports\default.py", line 101, in map_httpcore_exceptions
    yield
  File "D:\Programming\Python\Supp0rtBot\.venv\Lib\site-packages\httpx\_transports\default.py", line 394, in handle_async_request
    resp = await self._pool.handle_async_request(req)
           ^^^^^^^^^^^^^^^^^^^^^^^^^^^^^^^^^^^^^^^^^^
  File "D:\Programming\Python\Supp0rtBot\.venv\Lib\site-packages\httpcore\_async\connection_pool.py", line 256, in handle_async_request
    raise exc from None
  File "D:\Programming\Python\Supp0rtBot\.venv\Lib\site-packages\httpcore\_async\connection_pool.py", line 236, in handle_async_request
    response = await connection.handle_async_request(
               ^^^^^^^^^^^^^^^^^^^^^^^^^^^^^^^^^^^^^^
  File "D:\Programming\Python\Supp0rtBot\.venv\Lib\site-packages\httpcore\_async\connection.py", line 101, in handle_async_request
    raise exc
  File "D:\Programming\Python\Supp0rtBot\.venv\Lib\site-packages\httpcore\_async\connection.py", line 78, in handle_async_request
    stream = await self._connect(request)
             ^^^^^^^^^^^^^^^^^^^^^^^^^^^^
  File "D:\Programming\Python\Supp0rtBot\.venv\Lib\site-packages\httpcore\_async\connection.py", line 124, in _connect
    stream = await self._network_backend.connect_tcp(**kwargs)
             ^^^^^^^^^^^^^^^^^^^^^^^^^^^^^^^^^^^^^^^^^^^^^^^^^
  File "D:\Programming\Python\Supp0rtBot\.venv\Lib\site-packages\httpcore\_backends\auto.py", line 31, in connect_tcp
    return await self._backend.connect_tcp(
           ^^^^^^^^^^^^^^^^^^^^^^^^^^^^^^^^
  File "D:\Programming\Python\Supp0rtBot\.venv\Lib\site-packages\httpcore\_backends\anyio.py", line 113, in connect_tcp
    with map_exceptions(exc_map):
  File "C:\Users\38066\AppData\Local\Programs\Python\Python312\Lib\contextlib.py", line 158, in __exit__
    self.gen.throw(value)
  File "D:\Programming\Python\Supp0rtBot\.venv\Lib\site-packages\httpcore\_exceptions.py", line 14, in map_exceptions
    raise to_exc(exc) from exc
httpcore.ConnectError: [Errno 11001] getaddrinfo failed

The above exception was the direct cause of the following exception:

Traceback (most recent call last):
  File "D:\Programming\Python\Supp0rtBot\.venv\Lib\site-packages\telegram\request\_httpxrequest.py", line 293, in do_request
    res = await self._client.request(
          ^^^^^^^^^^^^^^^^^^^^^^^^^^^
  File "D:\Programming\Python\Supp0rtBot\.venv\Lib\site-packages\httpx\_client.py", line 1540, in request
    return await self.send(request, auth=auth, follow_redirects=follow_redirects)
           ^^^^^^^^^^^^^^^^^^^^^^^^^^^^^^^^^^^^^^^^^^^^^^^^^^^^^^^^^^^^^^^^^^^^^^
  File "D:\Programming\Python\Supp0rtBot\.venv\Lib\site-packages\httpx\_client.py", line 1629, in send
    response = await self._send_handling_auth(
               ^^^^^^^^^^^^^^^^^^^^^^^^^^^^^^^
  File "D:\Programming\Python\Supp0rtBot\.venv\Lib\site-packages\httpx\_client.py", line 1657, in _send_handling_auth
    response = await self._send_handling_redirects(
               ^^^^^^^^^^^^^^^^^^^^^^^^^^^^^^^^^^^^
  File "D:\Programming\Python\Supp0rtBot\.venv\Lib\site-packages\httpx\_client.py", line 1694, in _send_handling_redirects
    response = await self._send_single_request(request)
               ^^^^^^^^^^^^^^^^^^^^^^^^^^^^^^^^^^^^^^^^
  File "D:\Programming\Python\Supp0rtBot\.venv\Lib\site-packages\httpx\_client.py", line 1730, in _send_single_request
    response = await transport.handle_async_request(request)
               ^^^^^^^^^^^^^^^^^^^^^^^^^^^^^^^^^^^^^^^^^^^^^
  File "D:\Programming\Python\Supp0rtBot\.venv\Lib\site-packages\httpx\_transports\default.py", line 393, in handle_async_request
    with map_httpcore_exceptions():
  File "C:\Users\38066\AppData\Local\Programs\Python\Python312\Lib\contextlib.py", line 158, in __exit__
    self.gen.throw(value)
  File "D:\Programming\Python\Supp0rtBot\.venv\Lib\site-packages\httpx\_transports\default.py", line 118, in map_httpcore_exceptions
    raise mapped_exc(message) from exc
httpx.ConnectError: [Errno 11001] getaddrinfo failed

The above exception was the direct cause of the following exception:

Traceback (most recent call last):
  File "D:\Programming\Python\Supp0rtBot\.venv\Lib\site-packages\telegram\ext\_updater.py", line 750, in _network_loop_retry
    if not await do_action():
           ^^^^^^^^^^^^^^^^^
  File "D:\Programming\Python\Supp0rtBot\.venv\Lib\site-packages\telegram\ext\_updater.py", line 744, in do_action
    return action_cb_task.result()
           ^^^^^^^^^^^^^^^^^^^^^^^
  File "C:\Users\38066\AppData\Local\Programs\Python\Python312\Lib\asyncio\futures.py", line 203, in result
    raise self._exception.with_traceback(self._exception_tb)
  File "C:\Users\38066\AppData\Local\Programs\Python\Python312\Lib\asyncio\tasks.py", line 316, in __step_run_and_handle_result
    result = coro.throw(exc)
             ^^^^^^^^^^^^^^^
  File "D:\Programming\Python\Supp0rtBot\.venv\Lib\site-packages\telegram\ext\_updater.py", line 371, in polling_action_cb
    updates = await self.bot.get_updates(
              ^^^^^^^^^^^^^^^^^^^^^^^^^^^
  File "D:\Programming\Python\Supp0rtBot\.venv\Lib\site-packages\telegram\ext\_extbot.py", line 650, in get_updates
    updates = await super().get_updates(
              ^^^^^^^^^^^^^^^^^^^^^^^^^^
  File "D:\Programming\Python\Supp0rtBot\.venv\Lib\site-packages\telegram\_bot.py", line 4480, in get_updates
    await self._post(
  File "D:\Programming\Python\Supp0rtBot\.venv\Lib\site-packages\telegram\_bot.py", line 619, in _post
    return await self._do_post(
           ^^^^^^^^^^^^^^^^^^^^
  File "D:\Programming\Python\Supp0rtBot\.venv\Lib\site-packages\telegram\ext\_extbot.py", line 354, in _do_post
    return await super()._do_post(
           ^^^^^^^^^^^^^^^^^^^^^^^
  File "D:\Programming\Python\Supp0rtBot\.venv\Lib\site-packages\telegram\_bot.py", line 648, in _do_post
    result = await request.post(
             ^^^^^^^^^^^^^^^^^^^
  File "D:\Programming\Python\Supp0rtBot\.venv\Lib\site-packages\telegram\request\_baserequest.py", line 202, in post
    result = await self._request_wrapper(
             ^^^^^^^^^^^^^^^^^^^^^^^^^^^^
  File "D:\Programming\Python\Supp0rtBot\.venv\Lib\site-packages\telegram\request\_baserequest.py", line 334, in _request_wrapper
    code, payload = await self.do_request(
                    ^^^^^^^^^^^^^^^^^^^^^^
  File "D:\Programming\Python\Supp0rtBot\.venv\Lib\site-packages\telegram\request\_httpxrequest.py", line 317, in do_request
    raise NetworkError(f"httpx.{err.__class__.__name__}: {err}") from err
telegram.error.NetworkError: httpx.ConnectError: [Errno 11001] getaddrinfo failed
2025-05-17 09:24:04,294 - telegram.ext.Application - ERROR - No error handlers are registered, logging exception.
Traceback (most recent call last):
  File "D:\Programming\Python\Supp0rtBot\.venv\Lib\site-packages\httpx\_transports\default.py", line 101, in map_httpcore_exceptions
    yield
  File "D:\Programming\Python\Supp0rtBot\.venv\Lib\site-packages\httpx\_transports\default.py", line 394, in handle_async_request
    resp = await self._pool.handle_async_request(req)
           ^^^^^^^^^^^^^^^^^^^^^^^^^^^^^^^^^^^^^^^^^^
  File "D:\Programming\Python\Supp0rtBot\.venv\Lib\site-packages\httpcore\_async\connection_pool.py", line 256, in handle_async_request
    raise exc from None
  File "D:\Programming\Python\Supp0rtBot\.venv\Lib\site-packages\httpcore\_async\connection_pool.py", line 236, in handle_async_request
    response = await connection.handle_async_request(
               ^^^^^^^^^^^^^^^^^^^^^^^^^^^^^^^^^^^^^^
  File "D:\Programming\Python\Supp0rtBot\.venv\Lib\site-packages\httpcore\_async\connection.py", line 101, in handle_async_request
    raise exc
  File "D:\Programming\Python\Supp0rtBot\.venv\Lib\site-packages\httpcore\_async\connection.py", line 78, in handle_async_request
    stream = await self._connect(request)
             ^^^^^^^^^^^^^^^^^^^^^^^^^^^^
  File "D:\Programming\Python\Supp0rtBot\.venv\Lib\site-packages\httpcore\_async\connection.py", line 124, in _connect
    stream = await self._network_backend.connect_tcp(**kwargs)
             ^^^^^^^^^^^^^^^^^^^^^^^^^^^^^^^^^^^^^^^^^^^^^^^^^
  File "D:\Programming\Python\Supp0rtBot\.venv\Lib\site-packages\httpcore\_backends\auto.py", line 31, in connect_tcp
    return await self._backend.connect_tcp(
           ^^^^^^^^^^^^^^^^^^^^^^^^^^^^^^^^
  File "D:\Programming\Python\Supp0rtBot\.venv\Lib\site-packages\httpcore\_backends\anyio.py", line 113, in connect_tcp
    with map_exceptions(exc_map):
  File "C:\Users\38066\AppData\Local\Programs\Python\Python312\Lib\contextlib.py", line 158, in __exit__
    self.gen.throw(value)
  File "D:\Programming\Python\Supp0rtBot\.venv\Lib\site-packages\httpcore\_exceptions.py", line 14, in map_exceptions
    raise to_exc(exc) from exc
httpcore.ConnectError: [Errno 11001] getaddrinfo failed

The above exception was the direct cause of the following exception:

Traceback (most recent call last):
  File "D:\Programming\Python\Supp0rtBot\.venv\Lib\site-packages\telegram\request\_httpxrequest.py", line 293, in do_request
    res = await self._client.request(
          ^^^^^^^^^^^^^^^^^^^^^^^^^^^
  File "D:\Programming\Python\Supp0rtBot\.venv\Lib\site-packages\httpx\_client.py", line 1540, in request
    return await self.send(request, auth=auth, follow_redirects=follow_redirects)
           ^^^^^^^^^^^^^^^^^^^^^^^^^^^^^^^^^^^^^^^^^^^^^^^^^^^^^^^^^^^^^^^^^^^^^^
  File "D:\Programming\Python\Supp0rtBot\.venv\Lib\site-packages\httpx\_client.py", line 1629, in send
    response = await self._send_handling_auth(
               ^^^^^^^^^^^^^^^^^^^^^^^^^^^^^^^
  File "D:\Programming\Python\Supp0rtBot\.venv\Lib\site-packages\httpx\_client.py", line 1657, in _send_handling_auth
    response = await self._send_handling_redirects(
               ^^^^^^^^^^^^^^^^^^^^^^^^^^^^^^^^^^^^
  File "D:\Programming\Python\Supp0rtBot\.venv\Lib\site-packages\httpx\_client.py", line 1694, in _send_handling_redirects
    response = await self._send_single_request(request)
               ^^^^^^^^^^^^^^^^^^^^^^^^^^^^^^^^^^^^^^^^
  File "D:\Programming\Python\Supp0rtBot\.venv\Lib\site-packages\httpx\_client.py", line 1730, in _send_single_request
    response = await transport.handle_async_request(request)
               ^^^^^^^^^^^^^^^^^^^^^^^^^^^^^^^^^^^^^^^^^^^^^
  File "D:\Programming\Python\Supp0rtBot\.venv\Lib\site-packages\httpx\_transports\default.py", line 393, in handle_async_request
    with map_httpcore_exceptions():
  File "C:\Users\38066\AppData\Local\Programs\Python\Python312\Lib\contextlib.py", line 158, in __exit__
    self.gen.throw(value)
  File "D:\Programming\Python\Supp0rtBot\.venv\Lib\site-packages\httpx\_transports\default.py", line 118, in map_httpcore_exceptions
    raise mapped_exc(message) from exc
httpx.ConnectError: [Errno 11001] getaddrinfo failed

The above exception was the direct cause of the following exception:

Traceback (most recent call last):
  File "D:\Programming\Python\Supp0rtBot\.venv\Lib\site-packages\telegram\ext\_updater.py", line 750, in _network_loop_retry
    if not await do_action():
           ^^^^^^^^^^^^^^^^^
  File "D:\Programming\Python\Supp0rtBot\.venv\Lib\site-packages\telegram\ext\_updater.py", line 744, in do_action
    return action_cb_task.result()
           ^^^^^^^^^^^^^^^^^^^^^^^
  File "C:\Users\38066\AppData\Local\Programs\Python\Python312\Lib\asyncio\futures.py", line 203, in result
    raise self._exception.with_traceback(self._exception_tb)
  File "C:\Users\38066\AppData\Local\Programs\Python\Python312\Lib\asyncio\tasks.py", line 316, in __step_run_and_handle_result
    result = coro.throw(exc)
             ^^^^^^^^^^^^^^^
  File "D:\Programming\Python\Supp0rtBot\.venv\Lib\site-packages\telegram\ext\_updater.py", line 371, in polling_action_cb
    updates = await self.bot.get_updates(
              ^^^^^^^^^^^^^^^^^^^^^^^^^^^
  File "D:\Programming\Python\Supp0rtBot\.venv\Lib\site-packages\telegram\ext\_extbot.py", line 650, in get_updates
    updates = await super().get_updates(
              ^^^^^^^^^^^^^^^^^^^^^^^^^^
  File "D:\Programming\Python\Supp0rtBot\.venv\Lib\site-packages\telegram\_bot.py", line 4480, in get_updates
    await self._post(
  File "D:\Programming\Python\Supp0rtBot\.venv\Lib\site-packages\telegram\_bot.py", line 619, in _post
    return await self._do_post(
           ^^^^^^^^^^^^^^^^^^^^
  File "D:\Programming\Python\Supp0rtBot\.venv\Lib\site-packages\telegram\ext\_extbot.py", line 354, in _do_post
    return await super()._do_post(
           ^^^^^^^^^^^^^^^^^^^^^^^
  File "D:\Programming\Python\Supp0rtBot\.venv\Lib\site-packages\telegram\_bot.py", line 648, in _do_post
    result = await request.post(
             ^^^^^^^^^^^^^^^^^^^
  File "D:\Programming\Python\Supp0rtBot\.venv\Lib\site-packages\telegram\request\_baserequest.py", line 202, in post
    result = await self._request_wrapper(
             ^^^^^^^^^^^^^^^^^^^^^^^^^^^^
  File "D:\Programming\Python\Supp0rtBot\.venv\Lib\site-packages\telegram\request\_baserequest.py", line 334, in _request_wrapper
    code, payload = await self.do_request(
                    ^^^^^^^^^^^^^^^^^^^^^^
  File "D:\Programming\Python\Supp0rtBot\.venv\Lib\site-packages\telegram\request\_httpxrequest.py", line 317, in do_request
    raise NetworkError(f"httpx.{err.__class__.__name__}: {err}") from err
telegram.error.NetworkError: httpx.ConnectError: [Errno 11001] getaddrinfo failed
2025-05-17 09:24:07,695 - telegram.ext.Application - ERROR - No error handlers are registered, logging exception.
Traceback (most recent call last):
  File "D:\Programming\Python\Supp0rtBot\.venv\Lib\site-packages\httpx\_transports\default.py", line 101, in map_httpcore_exceptions
    yield
  File "D:\Programming\Python\Supp0rtBot\.venv\Lib\site-packages\httpx\_transports\default.py", line 394, in handle_async_request
    resp = await self._pool.handle_async_request(req)
           ^^^^^^^^^^^^^^^^^^^^^^^^^^^^^^^^^^^^^^^^^^
  File "D:\Programming\Python\Supp0rtBot\.venv\Lib\site-packages\httpcore\_async\connection_pool.py", line 256, in handle_async_request
    raise exc from None
  File "D:\Programming\Python\Supp0rtBot\.venv\Lib\site-packages\httpcore\_async\connection_pool.py", line 236, in handle_async_request
    response = await connection.handle_async_request(
               ^^^^^^^^^^^^^^^^^^^^^^^^^^^^^^^^^^^^^^
  File "D:\Programming\Python\Supp0rtBot\.venv\Lib\site-packages\httpcore\_async\connection.py", line 101, in handle_async_request
    raise exc
  File "D:\Programming\Python\Supp0rtBot\.venv\Lib\site-packages\httpcore\_async\connection.py", line 78, in handle_async_request
    stream = await self._connect(request)
             ^^^^^^^^^^^^^^^^^^^^^^^^^^^^
  File "D:\Programming\Python\Supp0rtBot\.venv\Lib\site-packages\httpcore\_async\connection.py", line 124, in _connect
    stream = await self._network_backend.connect_tcp(**kwargs)
             ^^^^^^^^^^^^^^^^^^^^^^^^^^^^^^^^^^^^^^^^^^^^^^^^^
  File "D:\Programming\Python\Supp0rtBot\.venv\Lib\site-packages\httpcore\_backends\auto.py", line 31, in connect_tcp
    return await self._backend.connect_tcp(
           ^^^^^^^^^^^^^^^^^^^^^^^^^^^^^^^^
  File "D:\Programming\Python\Supp0rtBot\.venv\Lib\site-packages\httpcore\_backends\anyio.py", line 113, in connect_tcp
    with map_exceptions(exc_map):
  File "C:\Users\38066\AppData\Local\Programs\Python\Python312\Lib\contextlib.py", line 158, in __exit__
    self.gen.throw(value)
  File "D:\Programming\Python\Supp0rtBot\.venv\Lib\site-packages\httpcore\_exceptions.py", line 14, in map_exceptions
    raise to_exc(exc) from exc
httpcore.ConnectError: [Errno 11001] getaddrinfo failed

The above exception was the direct cause of the following exception:

Traceback (most recent call last):
  File "D:\Programming\Python\Supp0rtBot\.venv\Lib\site-packages\telegram\request\_httpxrequest.py", line 293, in do_request
    res = await self._client.request(
          ^^^^^^^^^^^^^^^^^^^^^^^^^^^
  File "D:\Programming\Python\Supp0rtBot\.venv\Lib\site-packages\httpx\_client.py", line 1540, in request
    return await self.send(request, auth=auth, follow_redirects=follow_redirects)
           ^^^^^^^^^^^^^^^^^^^^^^^^^^^^^^^^^^^^^^^^^^^^^^^^^^^^^^^^^^^^^^^^^^^^^^
  File "D:\Programming\Python\Supp0rtBot\.venv\Lib\site-packages\httpx\_client.py", line 1629, in send
    response = await self._send_handling_auth(
               ^^^^^^^^^^^^^^^^^^^^^^^^^^^^^^^
  File "D:\Programming\Python\Supp0rtBot\.venv\Lib\site-packages\httpx\_client.py", line 1657, in _send_handling_auth
    response = await self._send_handling_redirects(
               ^^^^^^^^^^^^^^^^^^^^^^^^^^^^^^^^^^^^
  File "D:\Programming\Python\Supp0rtBot\.venv\Lib\site-packages\httpx\_client.py", line 1694, in _send_handling_redirects
    response = await self._send_single_request(request)
               ^^^^^^^^^^^^^^^^^^^^^^^^^^^^^^^^^^^^^^^^
  File "D:\Programming\Python\Supp0rtBot\.venv\Lib\site-packages\httpx\_client.py", line 1730, in _send_single_request
    response = await transport.handle_async_request(request)
               ^^^^^^^^^^^^^^^^^^^^^^^^^^^^^^^^^^^^^^^^^^^^^
  File "D:\Programming\Python\Supp0rtBot\.venv\Lib\site-packages\httpx\_transports\default.py", line 393, in handle_async_request
    with map_httpcore_exceptions():
  File "C:\Users\38066\AppData\Local\Programs\Python\Python312\Lib\contextlib.py", line 158, in __exit__
    self.gen.throw(value)
  File "D:\Programming\Python\Supp0rtBot\.venv\Lib\site-packages\httpx\_transports\default.py", line 118, in map_httpcore_exceptions
    raise mapped_exc(message) from exc
httpx.ConnectError: [Errno 11001] getaddrinfo failed

The above exception was the direct cause of the following exception:

Traceback (most recent call last):
  File "D:\Programming\Python\Supp0rtBot\.venv\Lib\site-packages\telegram\ext\_updater.py", line 750, in _network_loop_retry
    if not await do_action():
           ^^^^^^^^^^^^^^^^^
  File "D:\Programming\Python\Supp0rtBot\.venv\Lib\site-packages\telegram\ext\_updater.py", line 744, in do_action
    return action_cb_task.result()
           ^^^^^^^^^^^^^^^^^^^^^^^
  File "C:\Users\38066\AppData\Local\Programs\Python\Python312\Lib\asyncio\futures.py", line 203, in result
    raise self._exception.with_traceback(self._exception_tb)
  File "C:\Users\38066\AppData\Local\Programs\Python\Python312\Lib\asyncio\tasks.py", line 316, in __step_run_and_handle_result
    result = coro.throw(exc)
             ^^^^^^^^^^^^^^^
  File "D:\Programming\Python\Supp0rtBot\.venv\Lib\site-packages\telegram\ext\_updater.py", line 371, in polling_action_cb
    updates = await self.bot.get_updates(
              ^^^^^^^^^^^^^^^^^^^^^^^^^^^
  File "D:\Programming\Python\Supp0rtBot\.venv\Lib\site-packages\telegram\ext\_extbot.py", line 650, in get_updates
    updates = await super().get_updates(
              ^^^^^^^^^^^^^^^^^^^^^^^^^^
  File "D:\Programming\Python\Supp0rtBot\.venv\Lib\site-packages\telegram\_bot.py", line 4480, in get_updates
    await self._post(
  File "D:\Programming\Python\Supp0rtBot\.venv\Lib\site-packages\telegram\_bot.py", line 619, in _post
    return await self._do_post(
           ^^^^^^^^^^^^^^^^^^^^
  File "D:\Programming\Python\Supp0rtBot\.venv\Lib\site-packages\telegram\ext\_extbot.py", line 354, in _do_post
    return await super()._do_post(
           ^^^^^^^^^^^^^^^^^^^^^^^
  File "D:\Programming\Python\Supp0rtBot\.venv\Lib\site-packages\telegram\_bot.py", line 648, in _do_post
    result = await request.post(
             ^^^^^^^^^^^^^^^^^^^
  File "D:\Programming\Python\Supp0rtBot\.venv\Lib\site-packages\telegram\request\_baserequest.py", line 202, in post
    result = await self._request_wrapper(
             ^^^^^^^^^^^^^^^^^^^^^^^^^^^^
  File "D:\Programming\Python\Supp0rtBot\.venv\Lib\site-packages\telegram\request\_baserequest.py", line 334, in _request_wrapper
    code, payload = await self.do_request(
                    ^^^^^^^^^^^^^^^^^^^^^^
  File "D:\Programming\Python\Supp0rtBot\.venv\Lib\site-packages\telegram\request\_httpxrequest.py", line 317, in do_request
    raise NetworkError(f"httpx.{err.__class__.__name__}: {err}") from err
telegram.error.NetworkError: httpx.ConnectError: [Errno 11001] getaddrinfo failed
2025-05-17 09:24:28,110 - telegram.ext.Application - ERROR - No error handlers are registered, logging exception.
Traceback (most recent call last):
  File "D:\Programming\Python\Supp0rtBot\.venv\Lib\site-packages\httpx\_transports\default.py", line 101, in map_httpcore_exceptions
    yield
  File "D:\Programming\Python\Supp0rtBot\.venv\Lib\site-packages\httpx\_transports\default.py", line 394, in handle_async_request
    resp = await self._pool.handle_async_request(req)
           ^^^^^^^^^^^^^^^^^^^^^^^^^^^^^^^^^^^^^^^^^^
  File "D:\Programming\Python\Supp0rtBot\.venv\Lib\site-packages\httpcore\_async\connection_pool.py", line 256, in handle_async_request
    raise exc from None
  File "D:\Programming\Python\Supp0rtBot\.venv\Lib\site-packages\httpcore\_async\connection_pool.py", line 236, in handle_async_request
    response = await connection.handle_async_request(
               ^^^^^^^^^^^^^^^^^^^^^^^^^^^^^^^^^^^^^^
  File "D:\Programming\Python\Supp0rtBot\.venv\Lib\site-packages\httpcore\_async\connection.py", line 101, in handle_async_request
    raise exc
  File "D:\Programming\Python\Supp0rtBot\.venv\Lib\site-packages\httpcore\_async\connection.py", line 78, in handle_async_request
    stream = await self._connect(request)
             ^^^^^^^^^^^^^^^^^^^^^^^^^^^^
  File "D:\Programming\Python\Supp0rtBot\.venv\Lib\site-packages\httpcore\_async\connection.py", line 124, in _connect
    stream = await self._network_backend.connect_tcp(**kwargs)
             ^^^^^^^^^^^^^^^^^^^^^^^^^^^^^^^^^^^^^^^^^^^^^^^^^
  File "D:\Programming\Python\Supp0rtBot\.venv\Lib\site-packages\httpcore\_backends\auto.py", line 31, in connect_tcp
    return await self._backend.connect_tcp(
           ^^^^^^^^^^^^^^^^^^^^^^^^^^^^^^^^
  File "D:\Programming\Python\Supp0rtBot\.venv\Lib\site-packages\httpcore\_backends\anyio.py", line 113, in connect_tcp
    with map_exceptions(exc_map):
  File "C:\Users\38066\AppData\Local\Programs\Python\Python312\Lib\contextlib.py", line 158, in __exit__
    self.gen.throw(value)
  File "D:\Programming\Python\Supp0rtBot\.venv\Lib\site-packages\httpcore\_exceptions.py", line 14, in map_exceptions
    raise to_exc(exc) from exc
httpcore.ConnectError: [Errno 11001] getaddrinfo failed

The above exception was the direct cause of the following exception:

Traceback (most recent call last):
  File "D:\Programming\Python\Supp0rtBot\.venv\Lib\site-packages\telegram\request\_httpxrequest.py", line 293, in do_request
    res = await self._client.request(
          ^^^^^^^^^^^^^^^^^^^^^^^^^^^
  File "D:\Programming\Python\Supp0rtBot\.venv\Lib\site-packages\httpx\_client.py", line 1540, in request
    return await self.send(request, auth=auth, follow_redirects=follow_redirects)
           ^^^^^^^^^^^^^^^^^^^^^^^^^^^^^^^^^^^^^^^^^^^^^^^^^^^^^^^^^^^^^^^^^^^^^^
  File "D:\Programming\Python\Supp0rtBot\.venv\Lib\site-packages\httpx\_client.py", line 1629, in send
    response = await self._send_handling_auth(
               ^^^^^^^^^^^^^^^^^^^^^^^^^^^^^^^
  File "D:\Programming\Python\Supp0rtBot\.venv\Lib\site-packages\httpx\_client.py", line 1657, in _send_handling_auth
    response = await self._send_handling_redirects(
               ^^^^^^^^^^^^^^^^^^^^^^^^^^^^^^^^^^^^
  File "D:\Programming\Python\Supp0rtBot\.venv\Lib\site-packages\httpx\_client.py", line 1694, in _send_handling_redirects
    response = await self._send_single_request(request)
               ^^^^^^^^^^^^^^^^^^^^^^^^^^^^^^^^^^^^^^^^
  File "D:\Programming\Python\Supp0rtBot\.venv\Lib\site-packages\httpx\_client.py", line 1730, in _send_single_request
    response = await transport.handle_async_request(request)
               ^^^^^^^^^^^^^^^^^^^^^^^^^^^^^^^^^^^^^^^^^^^^^
  File "D:\Programming\Python\Supp0rtBot\.venv\Lib\site-packages\httpx\_transports\default.py", line 393, in handle_async_request
    with map_httpcore_exceptions():
  File "C:\Users\38066\AppData\Local\Programs\Python\Python312\Lib\contextlib.py", line 158, in __exit__
    self.gen.throw(value)
  File "D:\Programming\Python\Supp0rtBot\.venv\Lib\site-packages\httpx\_transports\default.py", line 118, in map_httpcore_exceptions
    raise mapped_exc(message) from exc
httpx.ConnectError: [Errno 11001] getaddrinfo failed

The above exception was the direct cause of the following exception:

Traceback (most recent call last):
  File "D:\Programming\Python\Supp0rtBot\.venv\Lib\site-packages\telegram\ext\_updater.py", line 750, in _network_loop_retry
    if not await do_action():
           ^^^^^^^^^^^^^^^^^
  File "D:\Programming\Python\Supp0rtBot\.venv\Lib\site-packages\telegram\ext\_updater.py", line 744, in do_action
    return action_cb_task.result()
           ^^^^^^^^^^^^^^^^^^^^^^^
  File "C:\Users\38066\AppData\Local\Programs\Python\Python312\Lib\asyncio\futures.py", line 203, in result
    raise self._exception.with_traceback(self._exception_tb)
  File "C:\Users\38066\AppData\Local\Programs\Python\Python312\Lib\asyncio\tasks.py", line 316, in __step_run_and_handle_result
    result = coro.throw(exc)
             ^^^^^^^^^^^^^^^
  File "D:\Programming\Python\Supp0rtBot\.venv\Lib\site-packages\telegram\ext\_updater.py", line 371, in polling_action_cb
    updates = await self.bot.get_updates(
              ^^^^^^^^^^^^^^^^^^^^^^^^^^^
  File "D:\Programming\Python\Supp0rtBot\.venv\Lib\site-packages\telegram\ext\_extbot.py", line 650, in get_updates
    updates = await super().get_updates(
              ^^^^^^^^^^^^^^^^^^^^^^^^^^
  File "D:\Programming\Python\Supp0rtBot\.venv\Lib\site-packages\telegram\_bot.py", line 4480, in get_updates
    await self._post(
  File "D:\Programming\Python\Supp0rtBot\.venv\Lib\site-packages\telegram\_bot.py", line 619, in _post
    return await self._do_post(
           ^^^^^^^^^^^^^^^^^^^^
  File "D:\Programming\Python\Supp0rtBot\.venv\Lib\site-packages\telegram\ext\_extbot.py", line 354, in _do_post
    return await super()._do_post(
           ^^^^^^^^^^^^^^^^^^^^^^^
  File "D:\Programming\Python\Supp0rtBot\.venv\Lib\site-packages\telegram\_bot.py", line 648, in _do_post
    result = await request.post(
             ^^^^^^^^^^^^^^^^^^^
  File "D:\Programming\Python\Supp0rtBot\.venv\Lib\site-packages\telegram\request\_baserequest.py", line 202, in post
    result = await self._request_wrapper(
             ^^^^^^^^^^^^^^^^^^^^^^^^^^^^
  File "D:\Programming\Python\Supp0rtBot\.venv\Lib\site-packages\telegram\request\_baserequest.py", line 334, in _request_wrapper
    code, payload = await self.do_request(
                    ^^^^^^^^^^^^^^^^^^^^^^
  File "D:\Programming\Python\Supp0rtBot\.venv\Lib\site-packages\telegram\request\_httpxrequest.py", line 317, in do_request
    raise NetworkError(f"httpx.{err.__class__.__name__}: {err}") from err
telegram.error.NetworkError: httpx.ConnectError: [Errno 11001] getaddrinfo failed
2025-05-17 09:24:40,250 - telegram.ext.Application - ERROR - No error handlers are registered, logging exception.
Traceback (most recent call last):
  File "D:\Programming\Python\Supp0rtBot\.venv\Lib\site-packages\httpx\_transports\default.py", line 101, in map_httpcore_exceptions
    yield
  File "D:\Programming\Python\Supp0rtBot\.venv\Lib\site-packages\httpx\_transports\default.py", line 394, in handle_async_request
    resp = await self._pool.handle_async_request(req)
           ^^^^^^^^^^^^^^^^^^^^^^^^^^^^^^^^^^^^^^^^^^
  File "D:\Programming\Python\Supp0rtBot\.venv\Lib\site-packages\httpcore\_async\connection_pool.py", line 256, in handle_async_request
    raise exc from None
  File "D:\Programming\Python\Supp0rtBot\.venv\Lib\site-packages\httpcore\_async\connection_pool.py", line 236, in handle_async_request
    response = await connection.handle_async_request(
               ^^^^^^^^^^^^^^^^^^^^^^^^^^^^^^^^^^^^^^
  File "D:\Programming\Python\Supp0rtBot\.venv\Lib\site-packages\httpcore\_async\connection.py", line 101, in handle_async_request
    raise exc
  File "D:\Programming\Python\Supp0rtBot\.venv\Lib\site-packages\httpcore\_async\connection.py", line 78, in handle_async_request
    stream = await self._connect(request)
             ^^^^^^^^^^^^^^^^^^^^^^^^^^^^
  File "D:\Programming\Python\Supp0rtBot\.venv\Lib\site-packages\httpcore\_async\connection.py", line 124, in _connect
    stream = await self._network_backend.connect_tcp(**kwargs)
             ^^^^^^^^^^^^^^^^^^^^^^^^^^^^^^^^^^^^^^^^^^^^^^^^^
  File "D:\Programming\Python\Supp0rtBot\.venv\Lib\site-packages\httpcore\_backends\auto.py", line 31, in connect_tcp
    return await self._backend.connect_tcp(
           ^^^^^^^^^^^^^^^^^^^^^^^^^^^^^^^^
  File "D:\Programming\Python\Supp0rtBot\.venv\Lib\site-packages\httpcore\_backends\anyio.py", line 113, in connect_tcp
    with map_exceptions(exc_map):
  File "C:\Users\38066\AppData\Local\Programs\Python\Python312\Lib\contextlib.py", line 158, in __exit__
    self.gen.throw(value)
  File "D:\Programming\Python\Supp0rtBot\.venv\Lib\site-packages\httpcore\_exceptions.py", line 14, in map_exceptions
    raise to_exc(exc) from exc
httpcore.ConnectError: [Errno 11001] getaddrinfo failed

The above exception was the direct cause of the following exception:

Traceback (most recent call last):
  File "D:\Programming\Python\Supp0rtBot\.venv\Lib\site-packages\telegram\request\_httpxrequest.py", line 293, in do_request
    res = await self._client.request(
          ^^^^^^^^^^^^^^^^^^^^^^^^^^^
  File "D:\Programming\Python\Supp0rtBot\.venv\Lib\site-packages\httpx\_client.py", line 1540, in request
    return await self.send(request, auth=auth, follow_redirects=follow_redirects)
           ^^^^^^^^^^^^^^^^^^^^^^^^^^^^^^^^^^^^^^^^^^^^^^^^^^^^^^^^^^^^^^^^^^^^^^
  File "D:\Programming\Python\Supp0rtBot\.venv\Lib\site-packages\httpx\_client.py", line 1629, in send
    response = await self._send_handling_auth(
               ^^^^^^^^^^^^^^^^^^^^^^^^^^^^^^^
  File "D:\Programming\Python\Supp0rtBot\.venv\Lib\site-packages\httpx\_client.py", line 1657, in _send_handling_auth
    response = await self._send_handling_redirects(
               ^^^^^^^^^^^^^^^^^^^^^^^^^^^^^^^^^^^^
  File "D:\Programming\Python\Supp0rtBot\.venv\Lib\site-packages\httpx\_client.py", line 1694, in _send_handling_redirects
    response = await self._send_single_request(request)
               ^^^^^^^^^^^^^^^^^^^^^^^^^^^^^^^^^^^^^^^^
  File "D:\Programming\Python\Supp0rtBot\.venv\Lib\site-packages\httpx\_client.py", line 1730, in _send_single_request
    response = await transport.handle_async_request(request)
               ^^^^^^^^^^^^^^^^^^^^^^^^^^^^^^^^^^^^^^^^^^^^^
  File "D:\Programming\Python\Supp0rtBot\.venv\Lib\site-packages\httpx\_transports\default.py", line 393, in handle_async_request
    with map_httpcore_exceptions():
  File "C:\Users\38066\AppData\Local\Programs\Python\Python312\Lib\contextlib.py", line 158, in __exit__
    self.gen.throw(value)
  File "D:\Programming\Python\Supp0rtBot\.venv\Lib\site-packages\httpx\_transports\default.py", line 118, in map_httpcore_exceptions
    raise mapped_exc(message) from exc
httpx.ConnectError: [Errno 11001] getaddrinfo failed

The above exception was the direct cause of the following exception:

Traceback (most recent call last):
  File "D:\Programming\Python\Supp0rtBot\.venv\Lib\site-packages\telegram\ext\_updater.py", line 750, in _network_loop_retry
    if not await do_action():
           ^^^^^^^^^^^^^^^^^
  File "D:\Programming\Python\Supp0rtBot\.venv\Lib\site-packages\telegram\ext\_updater.py", line 744, in do_action
    return action_cb_task.result()
           ^^^^^^^^^^^^^^^^^^^^^^^
  File "C:\Users\38066\AppData\Local\Programs\Python\Python312\Lib\asyncio\futures.py", line 203, in result
    raise self._exception.with_traceback(self._exception_tb)
  File "C:\Users\38066\AppData\Local\Programs\Python\Python312\Lib\asyncio\tasks.py", line 316, in __step_run_and_handle_result
    result = coro.throw(exc)
             ^^^^^^^^^^^^^^^
  File "D:\Programming\Python\Supp0rtBot\.venv\Lib\site-packages\telegram\ext\_updater.py", line 371, in polling_action_cb
    updates = await self.bot.get_updates(
              ^^^^^^^^^^^^^^^^^^^^^^^^^^^
  File "D:\Programming\Python\Supp0rtBot\.venv\Lib\site-packages\telegram\ext\_extbot.py", line 650, in get_updates
    updates = await super().get_updates(
              ^^^^^^^^^^^^^^^^^^^^^^^^^^
  File "D:\Programming\Python\Supp0rtBot\.venv\Lib\site-packages\telegram\_bot.py", line 4480, in get_updates
    await self._post(
  File "D:\Programming\Python\Supp0rtBot\.venv\Lib\site-packages\telegram\_bot.py", line 619, in _post
    return await self._do_post(
           ^^^^^^^^^^^^^^^^^^^^
  File "D:\Programming\Python\Supp0rtBot\.venv\Lib\site-packages\telegram\ext\_extbot.py", line 354, in _do_post
    return await super()._do_post(
           ^^^^^^^^^^^^^^^^^^^^^^^
  File "D:\Programming\Python\Supp0rtBot\.venv\Lib\site-packages\telegram\_bot.py", line 648, in _do_post
    result = await request.post(
             ^^^^^^^^^^^^^^^^^^^
  File "D:\Programming\Python\Supp0rtBot\.venv\Lib\site-packages\telegram\request\_baserequest.py", line 202, in post
    result = await self._request_wrapper(
             ^^^^^^^^^^^^^^^^^^^^^^^^^^^^
  File "D:\Programming\Python\Supp0rtBot\.venv\Lib\site-packages\telegram\request\_baserequest.py", line 334, in _request_wrapper
    code, payload = await self.do_request(
                    ^^^^^^^^^^^^^^^^^^^^^^
  File "D:\Programming\Python\Supp0rtBot\.venv\Lib\site-packages\telegram\request\_httpxrequest.py", line 317, in do_request
    raise NetworkError(f"httpx.{err.__class__.__name__}: {err}") from err
telegram.error.NetworkError: httpx.ConnectError: [Errno 11001] getaddrinfo failed
2025-05-17 09:24:41,815 - telegram.ext.Application - ERROR - No error handlers are registered, logging exception.
Traceback (most recent call last):
  File "D:\Programming\Python\Supp0rtBot\.venv\Lib\site-packages\httpx\_transports\default.py", line 101, in map_httpcore_exceptions
    yield
  File "D:\Programming\Python\Supp0rtBot\.venv\Lib\site-packages\httpx\_transports\default.py", line 394, in handle_async_request
    resp = await self._pool.handle_async_request(req)
           ^^^^^^^^^^^^^^^^^^^^^^^^^^^^^^^^^^^^^^^^^^
  File "D:\Programming\Python\Supp0rtBot\.venv\Lib\site-packages\httpcore\_async\connection_pool.py", line 256, in handle_async_request
    raise exc from None
  File "D:\Programming\Python\Supp0rtBot\.venv\Lib\site-packages\httpcore\_async\connection_pool.py", line 236, in handle_async_request
    response = await connection.handle_async_request(
               ^^^^^^^^^^^^^^^^^^^^^^^^^^^^^^^^^^^^^^
  File "D:\Programming\Python\Supp0rtBot\.venv\Lib\site-packages\httpcore\_async\connection.py", line 101, in handle_async_request
    raise exc
  File "D:\Programming\Python\Supp0rtBot\.venv\Lib\site-packages\httpcore\_async\connection.py", line 78, in handle_async_request
    stream = await self._connect(request)
             ^^^^^^^^^^^^^^^^^^^^^^^^^^^^
  File "D:\Programming\Python\Supp0rtBot\.venv\Lib\site-packages\httpcore\_async\connection.py", line 124, in _connect
    stream = await self._network_backend.connect_tcp(**kwargs)
             ^^^^^^^^^^^^^^^^^^^^^^^^^^^^^^^^^^^^^^^^^^^^^^^^^
  File "D:\Programming\Python\Supp0rtBot\.venv\Lib\site-packages\httpcore\_backends\auto.py", line 31, in connect_tcp
    return await self._backend.connect_tcp(
           ^^^^^^^^^^^^^^^^^^^^^^^^^^^^^^^^
  File "D:\Programming\Python\Supp0rtBot\.venv\Lib\site-packages\httpcore\_backends\anyio.py", line 113, in connect_tcp
    with map_exceptions(exc_map):
  File "C:\Users\38066\AppData\Local\Programs\Python\Python312\Lib\contextlib.py", line 158, in __exit__
    self.gen.throw(value)
  File "D:\Programming\Python\Supp0rtBot\.venv\Lib\site-packages\httpcore\_exceptions.py", line 14, in map_exceptions
    raise to_exc(exc) from exc
httpcore.ConnectError: [Errno 11001] getaddrinfo failed

The above exception was the direct cause of the following exception:

Traceback (most recent call last):
  File "D:\Programming\Python\Supp0rtBot\.venv\Lib\site-packages\telegram\request\_httpxrequest.py", line 293, in do_request
    res = await self._client.request(
          ^^^^^^^^^^^^^^^^^^^^^^^^^^^
  File "D:\Programming\Python\Supp0rtBot\.venv\Lib\site-packages\httpx\_client.py", line 1540, in request
    return await self.send(request, auth=auth, follow_redirects=follow_redirects)
           ^^^^^^^^^^^^^^^^^^^^^^^^^^^^^^^^^^^^^^^^^^^^^^^^^^^^^^^^^^^^^^^^^^^^^^
  File "D:\Programming\Python\Supp0rtBot\.venv\Lib\site-packages\httpx\_client.py", line 1629, in send
    response = await self._send_handling_auth(
               ^^^^^^^^^^^^^^^^^^^^^^^^^^^^^^^
  File "D:\Programming\Python\Supp0rtBot\.venv\Lib\site-packages\httpx\_client.py", line 1657, in _send_handling_auth
    response = await self._send_handling_redirects(
               ^^^^^^^^^^^^^^^^^^^^^^^^^^^^^^^^^^^^
  File "D:\Programming\Python\Supp0rtBot\.venv\Lib\site-packages\httpx\_client.py", line 1694, in _send_handling_redirects
    response = await self._send_single_request(request)
               ^^^^^^^^^^^^^^^^^^^^^^^^^^^^^^^^^^^^^^^^
  File "D:\Programming\Python\Supp0rtBot\.venv\Lib\site-packages\httpx\_client.py", line 1730, in _send_single_request
    response = await transport.handle_async_request(request)
               ^^^^^^^^^^^^^^^^^^^^^^^^^^^^^^^^^^^^^^^^^^^^^
  File "D:\Programming\Python\Supp0rtBot\.venv\Lib\site-packages\httpx\_transports\default.py", line 393, in handle_async_request
    with map_httpcore_exceptions():
  File "C:\Users\38066\AppData\Local\Programs\Python\Python312\Lib\contextlib.py", line 158, in __exit__
    self.gen.throw(value)
  File "D:\Programming\Python\Supp0rtBot\.venv\Lib\site-packages\httpx\_transports\default.py", line 118, in map_httpcore_exceptions
    raise mapped_exc(message) from exc
httpx.ConnectError: [Errno 11001] getaddrinfo failed

The above exception was the direct cause of the following exception:

Traceback (most recent call last):
  File "D:\Programming\Python\Supp0rtBot\.venv\Lib\site-packages\telegram\ext\_updater.py", line 750, in _network_loop_retry
    if not await do_action():
           ^^^^^^^^^^^^^^^^^
  File "D:\Programming\Python\Supp0rtBot\.venv\Lib\site-packages\telegram\ext\_updater.py", line 744, in do_action
    return action_cb_task.result()
           ^^^^^^^^^^^^^^^^^^^^^^^
  File "C:\Users\38066\AppData\Local\Programs\Python\Python312\Lib\asyncio\futures.py", line 203, in result
    raise self._exception.with_traceback(self._exception_tb)
  File "C:\Users\38066\AppData\Local\Programs\Python\Python312\Lib\asyncio\tasks.py", line 316, in __step_run_and_handle_result
    result = coro.throw(exc)
             ^^^^^^^^^^^^^^^
  File "D:\Programming\Python\Supp0rtBot\.venv\Lib\site-packages\telegram\ext\_updater.py", line 371, in polling_action_cb
    updates = await self.bot.get_updates(
              ^^^^^^^^^^^^^^^^^^^^^^^^^^^
  File "D:\Programming\Python\Supp0rtBot\.venv\Lib\site-packages\telegram\ext\_extbot.py", line 650, in get_updates
    updates = await super().get_updates(
              ^^^^^^^^^^^^^^^^^^^^^^^^^^
  File "D:\Programming\Python\Supp0rtBot\.venv\Lib\site-packages\telegram\_bot.py", line 4480, in get_updates
    await self._post(
  File "D:\Programming\Python\Supp0rtBot\.venv\Lib\site-packages\telegram\_bot.py", line 619, in _post
    return await self._do_post(
           ^^^^^^^^^^^^^^^^^^^^
  File "D:\Programming\Python\Supp0rtBot\.venv\Lib\site-packages\telegram\ext\_extbot.py", line 354, in _do_post
    return await super()._do_post(
           ^^^^^^^^^^^^^^^^^^^^^^^
  File "D:\Programming\Python\Supp0rtBot\.venv\Lib\site-packages\telegram\_bot.py", line 648, in _do_post
    result = await request.post(
             ^^^^^^^^^^^^^^^^^^^
  File "D:\Programming\Python\Supp0rtBot\.venv\Lib\site-packages\telegram\request\_baserequest.py", line 202, in post
    result = await self._request_wrapper(
             ^^^^^^^^^^^^^^^^^^^^^^^^^^^^
  File "D:\Programming\Python\Supp0rtBot\.venv\Lib\site-packages\telegram\request\_baserequest.py", line 334, in _request_wrapper
    code, payload = await self.do_request(
                    ^^^^^^^^^^^^^^^^^^^^^^
  File "D:\Programming\Python\Supp0rtBot\.venv\Lib\site-packages\telegram\request\_httpxrequest.py", line 317, in do_request
    raise NetworkError(f"httpx.{err.__class__.__name__}: {err}") from err
telegram.error.NetworkError: httpx.ConnectError: [Errno 11001] getaddrinfo failed
2025-05-17 09:24:44,093 - telegram.ext.Application - ERROR - No error handlers are registered, logging exception.
Traceback (most recent call last):
  File "D:\Programming\Python\Supp0rtBot\.venv\Lib\site-packages\httpx\_transports\default.py", line 101, in map_httpcore_exceptions
    yield
  File "D:\Programming\Python\Supp0rtBot\.venv\Lib\site-packages\httpx\_transports\default.py", line 394, in handle_async_request
    resp = await self._pool.handle_async_request(req)
           ^^^^^^^^^^^^^^^^^^^^^^^^^^^^^^^^^^^^^^^^^^
  File "D:\Programming\Python\Supp0rtBot\.venv\Lib\site-packages\httpcore\_async\connection_pool.py", line 256, in handle_async_request
    raise exc from None
  File "D:\Programming\Python\Supp0rtBot\.venv\Lib\site-packages\httpcore\_async\connection_pool.py", line 236, in handle_async_request
    response = await connection.handle_async_request(
               ^^^^^^^^^^^^^^^^^^^^^^^^^^^^^^^^^^^^^^
  File "D:\Programming\Python\Supp0rtBot\.venv\Lib\site-packages\httpcore\_async\connection.py", line 101, in handle_async_request
    raise exc
  File "D:\Programming\Python\Supp0rtBot\.venv\Lib\site-packages\httpcore\_async\connection.py", line 78, in handle_async_request
    stream = await self._connect(request)
             ^^^^^^^^^^^^^^^^^^^^^^^^^^^^
  File "D:\Programming\Python\Supp0rtBot\.venv\Lib\site-packages\httpcore\_async\connection.py", line 124, in _connect
    stream = await self._network_backend.connect_tcp(**kwargs)
             ^^^^^^^^^^^^^^^^^^^^^^^^^^^^^^^^^^^^^^^^^^^^^^^^^
  File "D:\Programming\Python\Supp0rtBot\.venv\Lib\site-packages\httpcore\_backends\auto.py", line 31, in connect_tcp
    return await self._backend.connect_tcp(
           ^^^^^^^^^^^^^^^^^^^^^^^^^^^^^^^^
  File "D:\Programming\Python\Supp0rtBot\.venv\Lib\site-packages\httpcore\_backends\anyio.py", line 113, in connect_tcp
    with map_exceptions(exc_map):
  File "C:\Users\38066\AppData\Local\Programs\Python\Python312\Lib\contextlib.py", line 158, in __exit__
    self.gen.throw(value)
  File "D:\Programming\Python\Supp0rtBot\.venv\Lib\site-packages\httpcore\_exceptions.py", line 14, in map_exceptions
    raise to_exc(exc) from exc
httpcore.ConnectError: [Errno 11001] getaddrinfo failed

The above exception was the direct cause of the following exception:

Traceback (most recent call last):
  File "D:\Programming\Python\Supp0rtBot\.venv\Lib\site-packages\telegram\request\_httpxrequest.py", line 293, in do_request
    res = await self._client.request(
          ^^^^^^^^^^^^^^^^^^^^^^^^^^^
  File "D:\Programming\Python\Supp0rtBot\.venv\Lib\site-packages\httpx\_client.py", line 1540, in request
    return await self.send(request, auth=auth, follow_redirects=follow_redirects)
           ^^^^^^^^^^^^^^^^^^^^^^^^^^^^^^^^^^^^^^^^^^^^^^^^^^^^^^^^^^^^^^^^^^^^^^
  File "D:\Programming\Python\Supp0rtBot\.venv\Lib\site-packages\httpx\_client.py", line 1629, in send
    response = await self._send_handling_auth(
               ^^^^^^^^^^^^^^^^^^^^^^^^^^^^^^^
  File "D:\Programming\Python\Supp0rtBot\.venv\Lib\site-packages\httpx\_client.py", line 1657, in _send_handling_auth
    response = await self._send_handling_redirects(
               ^^^^^^^^^^^^^^^^^^^^^^^^^^^^^^^^^^^^
  File "D:\Programming\Python\Supp0rtBot\.venv\Lib\site-packages\httpx\_client.py", line 1694, in _send_handling_redirects
    response = await self._send_single_request(request)
               ^^^^^^^^^^^^^^^^^^^^^^^^^^^^^^^^^^^^^^^^
  File "D:\Programming\Python\Supp0rtBot\.venv\Lib\site-packages\httpx\_client.py", line 1730, in _send_single_request
    response = await transport.handle_async_request(request)
               ^^^^^^^^^^^^^^^^^^^^^^^^^^^^^^^^^^^^^^^^^^^^^
  File "D:\Programming\Python\Supp0rtBot\.venv\Lib\site-packages\httpx\_transports\default.py", line 393, in handle_async_request
    with map_httpcore_exceptions():
  File "C:\Users\38066\AppData\Local\Programs\Python\Python312\Lib\contextlib.py", line 158, in __exit__
    self.gen.throw(value)
  File "D:\Programming\Python\Supp0rtBot\.venv\Lib\site-packages\httpx\_transports\default.py", line 118, in map_httpcore_exceptions
    raise mapped_exc(message) from exc
httpx.ConnectError: [Errno 11001] getaddrinfo failed

The above exception was the direct cause of the following exception:

Traceback (most recent call last):
  File "D:\Programming\Python\Supp0rtBot\.venv\Lib\site-packages\telegram\ext\_updater.py", line 750, in _network_loop_retry
    if not await do_action():
           ^^^^^^^^^^^^^^^^^
  File "D:\Programming\Python\Supp0rtBot\.venv\Lib\site-packages\telegram\ext\_updater.py", line 744, in do_action
    return action_cb_task.result()
           ^^^^^^^^^^^^^^^^^^^^^^^
  File "C:\Users\38066\AppData\Local\Programs\Python\Python312\Lib\asyncio\futures.py", line 203, in result
    raise self._exception.with_traceback(self._exception_tb)
  File "C:\Users\38066\AppData\Local\Programs\Python\Python312\Lib\asyncio\tasks.py", line 316, in __step_run_and_handle_result
    result = coro.throw(exc)
             ^^^^^^^^^^^^^^^
  File "D:\Programming\Python\Supp0rtBot\.venv\Lib\site-packages\telegram\ext\_updater.py", line 371, in polling_action_cb
    updates = await self.bot.get_updates(
              ^^^^^^^^^^^^^^^^^^^^^^^^^^^
  File "D:\Programming\Python\Supp0rtBot\.venv\Lib\site-packages\telegram\ext\_extbot.py", line 650, in get_updates
    updates = await super().get_updates(
              ^^^^^^^^^^^^^^^^^^^^^^^^^^
  File "D:\Programming\Python\Supp0rtBot\.venv\Lib\site-packages\telegram\_bot.py", line 4480, in get_updates
    await self._post(
  File "D:\Programming\Python\Supp0rtBot\.venv\Lib\site-packages\telegram\_bot.py", line 619, in _post
    return await self._do_post(
           ^^^^^^^^^^^^^^^^^^^^
  File "D:\Programming\Python\Supp0rtBot\.venv\Lib\site-packages\telegram\ext\_extbot.py", line 354, in _do_post
    return await super()._do_post(
           ^^^^^^^^^^^^^^^^^^^^^^^
  File "D:\Programming\Python\Supp0rtBot\.venv\Lib\site-packages\telegram\_bot.py", line 648, in _do_post
    result = await request.post(
             ^^^^^^^^^^^^^^^^^^^
  File "D:\Programming\Python\Supp0rtBot\.venv\Lib\site-packages\telegram\request\_baserequest.py", line 202, in post
    result = await self._request_wrapper(
             ^^^^^^^^^^^^^^^^^^^^^^^^^^^^
  File "D:\Programming\Python\Supp0rtBot\.venv\Lib\site-packages\telegram\request\_baserequest.py", line 334, in _request_wrapper
    code, payload = await self.do_request(
                    ^^^^^^^^^^^^^^^^^^^^^^
  File "D:\Programming\Python\Supp0rtBot\.venv\Lib\site-packages\telegram\request\_httpxrequest.py", line 317, in do_request
    raise NetworkError(f"httpx.{err.__class__.__name__}: {err}") from err
telegram.error.NetworkError: httpx.ConnectError: [Errno 11001] getaddrinfo failed
2025-05-17 09:24:47,483 - telegram.ext.Application - ERROR - No error handlers are registered, logging exception.
Traceback (most recent call last):
  File "D:\Programming\Python\Supp0rtBot\.venv\Lib\site-packages\httpx\_transports\default.py", line 101, in map_httpcore_exceptions
    yield
  File "D:\Programming\Python\Supp0rtBot\.venv\Lib\site-packages\httpx\_transports\default.py", line 394, in handle_async_request
    resp = await self._pool.handle_async_request(req)
           ^^^^^^^^^^^^^^^^^^^^^^^^^^^^^^^^^^^^^^^^^^
  File "D:\Programming\Python\Supp0rtBot\.venv\Lib\site-packages\httpcore\_async\connection_pool.py", line 256, in handle_async_request
    raise exc from None
  File "D:\Programming\Python\Supp0rtBot\.venv\Lib\site-packages\httpcore\_async\connection_pool.py", line 236, in handle_async_request
    response = await connection.handle_async_request(
               ^^^^^^^^^^^^^^^^^^^^^^^^^^^^^^^^^^^^^^
  File "D:\Programming\Python\Supp0rtBot\.venv\Lib\site-packages\httpcore\_async\connection.py", line 101, in handle_async_request
    raise exc
  File "D:\Programming\Python\Supp0rtBot\.venv\Lib\site-packages\httpcore\_async\connection.py", line 78, in handle_async_request
    stream = await self._connect(request)
             ^^^^^^^^^^^^^^^^^^^^^^^^^^^^
  File "D:\Programming\Python\Supp0rtBot\.venv\Lib\site-packages\httpcore\_async\connection.py", line 124, in _connect
    stream = await self._network_backend.connect_tcp(**kwargs)
             ^^^^^^^^^^^^^^^^^^^^^^^^^^^^^^^^^^^^^^^^^^^^^^^^^
  File "D:\Programming\Python\Supp0rtBot\.venv\Lib\site-packages\httpcore\_backends\auto.py", line 31, in connect_tcp
    return await self._backend.connect_tcp(
           ^^^^^^^^^^^^^^^^^^^^^^^^^^^^^^^^
  File "D:\Programming\Python\Supp0rtBot\.venv\Lib\site-packages\httpcore\_backends\anyio.py", line 113, in connect_tcp
    with map_exceptions(exc_map):
  File "C:\Users\38066\AppData\Local\Programs\Python\Python312\Lib\contextlib.py", line 158, in __exit__
    self.gen.throw(value)
  File "D:\Programming\Python\Supp0rtBot\.venv\Lib\site-packages\httpcore\_exceptions.py", line 14, in map_exceptions
    raise to_exc(exc) from exc
httpcore.ConnectError: [Errno 11001] getaddrinfo failed

The above exception was the direct cause of the following exception:

Traceback (most recent call last):
  File "D:\Programming\Python\Supp0rtBot\.venv\Lib\site-packages\telegram\request\_httpxrequest.py", line 293, in do_request
    res = await self._client.request(
          ^^^^^^^^^^^^^^^^^^^^^^^^^^^
  File "D:\Programming\Python\Supp0rtBot\.venv\Lib\site-packages\httpx\_client.py", line 1540, in request
    return await self.send(request, auth=auth, follow_redirects=follow_redirects)
           ^^^^^^^^^^^^^^^^^^^^^^^^^^^^^^^^^^^^^^^^^^^^^^^^^^^^^^^^^^^^^^^^^^^^^^
  File "D:\Programming\Python\Supp0rtBot\.venv\Lib\site-packages\httpx\_client.py", line 1629, in send
    response = await self._send_handling_auth(
               ^^^^^^^^^^^^^^^^^^^^^^^^^^^^^^^
  File "D:\Programming\Python\Supp0rtBot\.venv\Lib\site-packages\httpx\_client.py", line 1657, in _send_handling_auth
    response = await self._send_handling_redirects(
               ^^^^^^^^^^^^^^^^^^^^^^^^^^^^^^^^^^^^
  File "D:\Programming\Python\Supp0rtBot\.venv\Lib\site-packages\httpx\_client.py", line 1694, in _send_handling_redirects
    response = await self._send_single_request(request)
               ^^^^^^^^^^^^^^^^^^^^^^^^^^^^^^^^^^^^^^^^
  File "D:\Programming\Python\Supp0rtBot\.venv\Lib\site-packages\httpx\_client.py", line 1730, in _send_single_request
    response = await transport.handle_async_request(request)
               ^^^^^^^^^^^^^^^^^^^^^^^^^^^^^^^^^^^^^^^^^^^^^
  File "D:\Programming\Python\Supp0rtBot\.venv\Lib\site-packages\httpx\_transports\default.py", line 393, in handle_async_request
    with map_httpcore_exceptions():
  File "C:\Users\38066\AppData\Local\Programs\Python\Python312\Lib\contextlib.py", line 158, in __exit__
    self.gen.throw(value)
  File "D:\Programming\Python\Supp0rtBot\.venv\Lib\site-packages\httpx\_transports\default.py", line 118, in map_httpcore_exceptions
    raise mapped_exc(message) from exc
httpx.ConnectError: [Errno 11001] getaddrinfo failed

The above exception was the direct cause of the following exception:

Traceback (most recent call last):
  File "D:\Programming\Python\Supp0rtBot\.venv\Lib\site-packages\telegram\ext\_updater.py", line 750, in _network_loop_retry
    if not await do_action():
           ^^^^^^^^^^^^^^^^^
  File "D:\Programming\Python\Supp0rtBot\.venv\Lib\site-packages\telegram\ext\_updater.py", line 744, in do_action
    return action_cb_task.result()
           ^^^^^^^^^^^^^^^^^^^^^^^
  File "C:\Users\38066\AppData\Local\Programs\Python\Python312\Lib\asyncio\futures.py", line 203, in result
    raise self._exception.with_traceback(self._exception_tb)
  File "C:\Users\38066\AppData\Local\Programs\Python\Python312\Lib\asyncio\tasks.py", line 316, in __step_run_and_handle_result
    result = coro.throw(exc)
             ^^^^^^^^^^^^^^^
  File "D:\Programming\Python\Supp0rtBot\.venv\Lib\site-packages\telegram\ext\_updater.py", line 371, in polling_action_cb
    updates = await self.bot.get_updates(
              ^^^^^^^^^^^^^^^^^^^^^^^^^^^
  File "D:\Programming\Python\Supp0rtBot\.venv\Lib\site-packages\telegram\ext\_extbot.py", line 650, in get_updates
    updates = await super().get_updates(
              ^^^^^^^^^^^^^^^^^^^^^^^^^^
  File "D:\Programming\Python\Supp0rtBot\.venv\Lib\site-packages\telegram\_bot.py", line 4480, in get_updates
    await self._post(
  File "D:\Programming\Python\Supp0rtBot\.venv\Lib\site-packages\telegram\_bot.py", line 619, in _post
    return await self._do_post(
           ^^^^^^^^^^^^^^^^^^^^
  File "D:\Programming\Python\Supp0rtBot\.venv\Lib\site-packages\telegram\ext\_extbot.py", line 354, in _do_post
    return await super()._do_post(
           ^^^^^^^^^^^^^^^^^^^^^^^
  File "D:\Programming\Python\Supp0rtBot\.venv\Lib\site-packages\telegram\_bot.py", line 648, in _do_post
    result = await request.post(
             ^^^^^^^^^^^^^^^^^^^
  File "D:\Programming\Python\Supp0rtBot\.venv\Lib\site-packages\telegram\request\_baserequest.py", line 202, in post
    result = await self._request_wrapper(
             ^^^^^^^^^^^^^^^^^^^^^^^^^^^^
  File "D:\Programming\Python\Supp0rtBot\.venv\Lib\site-packages\telegram\request\_baserequest.py", line 334, in _request_wrapper
    code, payload = await self.do_request(
                    ^^^^^^^^^^^^^^^^^^^^^^
  File "D:\Programming\Python\Supp0rtBot\.venv\Lib\site-packages\telegram\request\_httpxrequest.py", line 317, in do_request
    raise NetworkError(f"httpx.{err.__class__.__name__}: {err}") from err
telegram.error.NetworkError: httpx.ConnectError: [Errno 11001] getaddrinfo failed
2025-05-17 09:24:52,604 - telegram.ext.Application - ERROR - No error handlers are registered, logging exception.
Traceback (most recent call last):
  File "D:\Programming\Python\Supp0rtBot\.venv\Lib\site-packages\httpx\_transports\default.py", line 101, in map_httpcore_exceptions
    yield
  File "D:\Programming\Python\Supp0rtBot\.venv\Lib\site-packages\httpx\_transports\default.py", line 394, in handle_async_request
    resp = await self._pool.handle_async_request(req)
           ^^^^^^^^^^^^^^^^^^^^^^^^^^^^^^^^^^^^^^^^^^
  File "D:\Programming\Python\Supp0rtBot\.venv\Lib\site-packages\httpcore\_async\connection_pool.py", line 256, in handle_async_request
    raise exc from None
  File "D:\Programming\Python\Supp0rtBot\.venv\Lib\site-packages\httpcore\_async\connection_pool.py", line 236, in handle_async_request
    response = await connection.handle_async_request(
               ^^^^^^^^^^^^^^^^^^^^^^^^^^^^^^^^^^^^^^
  File "D:\Programming\Python\Supp0rtBot\.venv\Lib\site-packages\httpcore\_async\connection.py", line 101, in handle_async_request
    raise exc
  File "D:\Programming\Python\Supp0rtBot\.venv\Lib\site-packages\httpcore\_async\connection.py", line 78, in handle_async_request
    stream = await self._connect(request)
             ^^^^^^^^^^^^^^^^^^^^^^^^^^^^
  File "D:\Programming\Python\Supp0rtBot\.venv\Lib\site-packages\httpcore\_async\connection.py", line 124, in _connect
    stream = await self._network_backend.connect_tcp(**kwargs)
             ^^^^^^^^^^^^^^^^^^^^^^^^^^^^^^^^^^^^^^^^^^^^^^^^^
  File "D:\Programming\Python\Supp0rtBot\.venv\Lib\site-packages\httpcore\_backends\auto.py", line 31, in connect_tcp
    return await self._backend.connect_tcp(
           ^^^^^^^^^^^^^^^^^^^^^^^^^^^^^^^^
  File "D:\Programming\Python\Supp0rtBot\.venv\Lib\site-packages\httpcore\_backends\anyio.py", line 113, in connect_tcp
    with map_exceptions(exc_map):
  File "C:\Users\38066\AppData\Local\Programs\Python\Python312\Lib\contextlib.py", line 158, in __exit__
    self.gen.throw(value)
  File "D:\Programming\Python\Supp0rtBot\.venv\Lib\site-packages\httpcore\_exceptions.py", line 14, in map_exceptions
    raise to_exc(exc) from exc
httpcore.ConnectError: [Errno 11001] getaddrinfo failed

The above exception was the direct cause of the following exception:

Traceback (most recent call last):
  File "D:\Programming\Python\Supp0rtBot\.venv\Lib\site-packages\telegram\request\_httpxrequest.py", line 293, in do_request
    res = await self._client.request(
          ^^^^^^^^^^^^^^^^^^^^^^^^^^^
  File "D:\Programming\Python\Supp0rtBot\.venv\Lib\site-packages\httpx\_client.py", line 1540, in request
    return await self.send(request, auth=auth, follow_redirects=follow_redirects)
           ^^^^^^^^^^^^^^^^^^^^^^^^^^^^^^^^^^^^^^^^^^^^^^^^^^^^^^^^^^^^^^^^^^^^^^
  File "D:\Programming\Python\Supp0rtBot\.venv\Lib\site-packages\httpx\_client.py", line 1629, in send
    response = await self._send_handling_auth(
               ^^^^^^^^^^^^^^^^^^^^^^^^^^^^^^^
  File "D:\Programming\Python\Supp0rtBot\.venv\Lib\site-packages\httpx\_client.py", line 1657, in _send_handling_auth
    response = await self._send_handling_redirects(
               ^^^^^^^^^^^^^^^^^^^^^^^^^^^^^^^^^^^^
  File "D:\Programming\Python\Supp0rtBot\.venv\Lib\site-packages\httpx\_client.py", line 1694, in _send_handling_redirects
    response = await self._send_single_request(request)
               ^^^^^^^^^^^^^^^^^^^^^^^^^^^^^^^^^^^^^^^^
  File "D:\Programming\Python\Supp0rtBot\.venv\Lib\site-packages\httpx\_client.py", line 1730, in _send_single_request
    response = await transport.handle_async_request(request)
               ^^^^^^^^^^^^^^^^^^^^^^^^^^^^^^^^^^^^^^^^^^^^^
  File "D:\Programming\Python\Supp0rtBot\.venv\Lib\site-packages\httpx\_transports\default.py", line 393, in handle_async_request
    with map_httpcore_exceptions():
  File "C:\Users\38066\AppData\Local\Programs\Python\Python312\Lib\contextlib.py", line 158, in __exit__
    self.gen.throw(value)
  File "D:\Programming\Python\Supp0rtBot\.venv\Lib\site-packages\httpx\_transports\default.py", line 118, in map_httpcore_exceptions
    raise mapped_exc(message) from exc
httpx.ConnectError: [Errno 11001] getaddrinfo failed

The above exception was the direct cause of the following exception:

Traceback (most recent call last):
  File "D:\Programming\Python\Supp0rtBot\.venv\Lib\site-packages\telegram\ext\_updater.py", line 750, in _network_loop_retry
    if not await do_action():
           ^^^^^^^^^^^^^^^^^
  File "D:\Programming\Python\Supp0rtBot\.venv\Lib\site-packages\telegram\ext\_updater.py", line 744, in do_action
    return action_cb_task.result()
           ^^^^^^^^^^^^^^^^^^^^^^^
  File "C:\Users\38066\AppData\Local\Programs\Python\Python312\Lib\asyncio\futures.py", line 203, in result
    raise self._exception.with_traceback(self._exception_tb)
  File "C:\Users\38066\AppData\Local\Programs\Python\Python312\Lib\asyncio\tasks.py", line 316, in __step_run_and_handle_result
    result = coro.throw(exc)
             ^^^^^^^^^^^^^^^
  File "D:\Programming\Python\Supp0rtBot\.venv\Lib\site-packages\telegram\ext\_updater.py", line 371, in polling_action_cb
    updates = await self.bot.get_updates(
              ^^^^^^^^^^^^^^^^^^^^^^^^^^^
  File "D:\Programming\Python\Supp0rtBot\.venv\Lib\site-packages\telegram\ext\_extbot.py", line 650, in get_updates
    updates = await super().get_updates(
              ^^^^^^^^^^^^^^^^^^^^^^^^^^
  File "D:\Programming\Python\Supp0rtBot\.venv\Lib\site-packages\telegram\_bot.py", line 4480, in get_updates
    await self._post(
  File "D:\Programming\Python\Supp0rtBot\.venv\Lib\site-packages\telegram\_bot.py", line 619, in _post
    return await self._do_post(
           ^^^^^^^^^^^^^^^^^^^^
  File "D:\Programming\Python\Supp0rtBot\.venv\Lib\site-packages\telegram\ext\_extbot.py", line 354, in _do_post
    return await super()._do_post(
           ^^^^^^^^^^^^^^^^^^^^^^^
  File "D:\Programming\Python\Supp0rtBot\.venv\Lib\site-packages\telegram\_bot.py", line 648, in _do_post
    result = await request.post(
             ^^^^^^^^^^^^^^^^^^^
  File "D:\Programming\Python\Supp0rtBot\.venv\Lib\site-packages\telegram\request\_baserequest.py", line 202, in post
    result = await self._request_wrapper(
             ^^^^^^^^^^^^^^^^^^^^^^^^^^^^
  File "D:\Programming\Python\Supp0rtBot\.venv\Lib\site-packages\telegram\request\_baserequest.py", line 334, in _request_wrapper
    code, payload = await self.do_request(
                    ^^^^^^^^^^^^^^^^^^^^^^
  File "D:\Programming\Python\Supp0rtBot\.venv\Lib\site-packages\telegram\request\_httpxrequest.py", line 317, in do_request
    raise NetworkError(f"httpx.{err.__class__.__name__}: {err}") from err
telegram.error.NetworkError: httpx.ConnectError: [Errno 11001] getaddrinfo failed
2025-05-17 09:25:00,205 - telegram.ext.Application - ERROR - No error handlers are registered, logging exception.
Traceback (most recent call last):
  File "D:\Programming\Python\Supp0rtBot\.venv\Lib\site-packages\httpx\_transports\default.py", line 101, in map_httpcore_exceptions
    yield
  File "D:\Programming\Python\Supp0rtBot\.venv\Lib\site-packages\httpx\_transports\default.py", line 394, in handle_async_request
    resp = await self._pool.handle_async_request(req)
           ^^^^^^^^^^^^^^^^^^^^^^^^^^^^^^^^^^^^^^^^^^
  File "D:\Programming\Python\Supp0rtBot\.venv\Lib\site-packages\httpcore\_async\connection_pool.py", line 256, in handle_async_request
    raise exc from None
  File "D:\Programming\Python\Supp0rtBot\.venv\Lib\site-packages\httpcore\_async\connection_pool.py", line 236, in handle_async_request
    response = await connection.handle_async_request(
               ^^^^^^^^^^^^^^^^^^^^^^^^^^^^^^^^^^^^^^
  File "D:\Programming\Python\Supp0rtBot\.venv\Lib\site-packages\httpcore\_async\connection.py", line 101, in handle_async_request
    raise exc
  File "D:\Programming\Python\Supp0rtBot\.venv\Lib\site-packages\httpcore\_async\connection.py", line 78, in handle_async_request
    stream = await self._connect(request)
             ^^^^^^^^^^^^^^^^^^^^^^^^^^^^
  File "D:\Programming\Python\Supp0rtBot\.venv\Lib\site-packages\httpcore\_async\connection.py", line 124, in _connect
    stream = await self._network_backend.connect_tcp(**kwargs)
             ^^^^^^^^^^^^^^^^^^^^^^^^^^^^^^^^^^^^^^^^^^^^^^^^^
  File "D:\Programming\Python\Supp0rtBot\.venv\Lib\site-packages\httpcore\_backends\auto.py", line 31, in connect_tcp
    return await self._backend.connect_tcp(
           ^^^^^^^^^^^^^^^^^^^^^^^^^^^^^^^^
  File "D:\Programming\Python\Supp0rtBot\.venv\Lib\site-packages\httpcore\_backends\anyio.py", line 113, in connect_tcp
    with map_exceptions(exc_map):
  File "C:\Users\38066\AppData\Local\Programs\Python\Python312\Lib\contextlib.py", line 158, in __exit__
    self.gen.throw(value)
  File "D:\Programming\Python\Supp0rtBot\.venv\Lib\site-packages\httpcore\_exceptions.py", line 14, in map_exceptions
    raise to_exc(exc) from exc
httpcore.ConnectError: [Errno 11001] getaddrinfo failed

The above exception was the direct cause of the following exception:

Traceback (most recent call last):
  File "D:\Programming\Python\Supp0rtBot\.venv\Lib\site-packages\telegram\request\_httpxrequest.py", line 293, in do_request
    res = await self._client.request(
          ^^^^^^^^^^^^^^^^^^^^^^^^^^^
  File "D:\Programming\Python\Supp0rtBot\.venv\Lib\site-packages\httpx\_client.py", line 1540, in request
    return await self.send(request, auth=auth, follow_redirects=follow_redirects)
           ^^^^^^^^^^^^^^^^^^^^^^^^^^^^^^^^^^^^^^^^^^^^^^^^^^^^^^^^^^^^^^^^^^^^^^
  File "D:\Programming\Python\Supp0rtBot\.venv\Lib\site-packages\httpx\_client.py", line 1629, in send
    response = await self._send_handling_auth(
               ^^^^^^^^^^^^^^^^^^^^^^^^^^^^^^^
  File "D:\Programming\Python\Supp0rtBot\.venv\Lib\site-packages\httpx\_client.py", line 1657, in _send_handling_auth
    response = await self._send_handling_redirects(
               ^^^^^^^^^^^^^^^^^^^^^^^^^^^^^^^^^^^^
  File "D:\Programming\Python\Supp0rtBot\.venv\Lib\site-packages\httpx\_client.py", line 1694, in _send_handling_redirects
    response = await self._send_single_request(request)
               ^^^^^^^^^^^^^^^^^^^^^^^^^^^^^^^^^^^^^^^^
  File "D:\Programming\Python\Supp0rtBot\.venv\Lib\site-packages\httpx\_client.py", line 1730, in _send_single_request
    response = await transport.handle_async_request(request)
               ^^^^^^^^^^^^^^^^^^^^^^^^^^^^^^^^^^^^^^^^^^^^^
  File "D:\Programming\Python\Supp0rtBot\.venv\Lib\site-packages\httpx\_transports\default.py", line 393, in handle_async_request
    with map_httpcore_exceptions():
  File "C:\Users\38066\AppData\Local\Programs\Python\Python312\Lib\contextlib.py", line 158, in __exit__
    self.gen.throw(value)
  File "D:\Programming\Python\Supp0rtBot\.venv\Lib\site-packages\httpx\_transports\default.py", line 118, in map_httpcore_exceptions
    raise mapped_exc(message) from exc
httpx.ConnectError: [Errno 11001] getaddrinfo failed

The above exception was the direct cause of the following exception:

Traceback (most recent call last):
  File "D:\Programming\Python\Supp0rtBot\.venv\Lib\site-packages\telegram\ext\_updater.py", line 750, in _network_loop_retry
    if not await do_action():
           ^^^^^^^^^^^^^^^^^
  File "D:\Programming\Python\Supp0rtBot\.venv\Lib\site-packages\telegram\ext\_updater.py", line 744, in do_action
    return action_cb_task.result()
           ^^^^^^^^^^^^^^^^^^^^^^^
  File "C:\Users\38066\AppData\Local\Programs\Python\Python312\Lib\asyncio\futures.py", line 203, in result
    raise self._exception.with_traceback(self._exception_tb)
  File "C:\Users\38066\AppData\Local\Programs\Python\Python312\Lib\asyncio\tasks.py", line 316, in __step_run_and_handle_result
    result = coro.throw(exc)
             ^^^^^^^^^^^^^^^
  File "D:\Programming\Python\Supp0rtBot\.venv\Lib\site-packages\telegram\ext\_updater.py", line 371, in polling_action_cb
    updates = await self.bot.get_updates(
              ^^^^^^^^^^^^^^^^^^^^^^^^^^^
  File "D:\Programming\Python\Supp0rtBot\.venv\Lib\site-packages\telegram\ext\_extbot.py", line 650, in get_updates
    updates = await super().get_updates(
              ^^^^^^^^^^^^^^^^^^^^^^^^^^
  File "D:\Programming\Python\Supp0rtBot\.venv\Lib\site-packages\telegram\_bot.py", line 4480, in get_updates
    await self._post(
  File "D:\Programming\Python\Supp0rtBot\.venv\Lib\site-packages\telegram\_bot.py", line 619, in _post
    return await self._do_post(
           ^^^^^^^^^^^^^^^^^^^^
  File "D:\Programming\Python\Supp0rtBot\.venv\Lib\site-packages\telegram\ext\_extbot.py", line 354, in _do_post
    return await super()._do_post(
           ^^^^^^^^^^^^^^^^^^^^^^^
  File "D:\Programming\Python\Supp0rtBot\.venv\Lib\site-packages\telegram\_bot.py", line 648, in _do_post
    result = await request.post(
             ^^^^^^^^^^^^^^^^^^^
  File "D:\Programming\Python\Supp0rtBot\.venv\Lib\site-packages\telegram\request\_baserequest.py", line 202, in post
    result = await self._request_wrapper(
             ^^^^^^^^^^^^^^^^^^^^^^^^^^^^
  File "D:\Programming\Python\Supp0rtBot\.venv\Lib\site-packages\telegram\request\_baserequest.py", line 334, in _request_wrapper
    code, payload = await self.do_request(
                    ^^^^^^^^^^^^^^^^^^^^^^
  File "D:\Programming\Python\Supp0rtBot\.venv\Lib\site-packages\telegram\request\_httpxrequest.py", line 317, in do_request
    raise NetworkError(f"httpx.{err.__class__.__name__}: {err}") from err
telegram.error.NetworkError: httpx.ConnectError: [Errno 11001] getaddrinfo failed
2025-05-17 09:25:11,599 - telegram.ext.Application - ERROR - No error handlers are registered, logging exception.
Traceback (most recent call last):
  File "D:\Programming\Python\Supp0rtBot\.venv\Lib\site-packages\httpx\_transports\default.py", line 101, in map_httpcore_exceptions
    yield
  File "D:\Programming\Python\Supp0rtBot\.venv\Lib\site-packages\httpx\_transports\default.py", line 394, in handle_async_request
    resp = await self._pool.handle_async_request(req)
           ^^^^^^^^^^^^^^^^^^^^^^^^^^^^^^^^^^^^^^^^^^
  File "D:\Programming\Python\Supp0rtBot\.venv\Lib\site-packages\httpcore\_async\connection_pool.py", line 256, in handle_async_request
    raise exc from None
  File "D:\Programming\Python\Supp0rtBot\.venv\Lib\site-packages\httpcore\_async\connection_pool.py", line 236, in handle_async_request
    response = await connection.handle_async_request(
               ^^^^^^^^^^^^^^^^^^^^^^^^^^^^^^^^^^^^^^
  File "D:\Programming\Python\Supp0rtBot\.venv\Lib\site-packages\httpcore\_async\connection.py", line 101, in handle_async_request
    raise exc
  File "D:\Programming\Python\Supp0rtBot\.venv\Lib\site-packages\httpcore\_async\connection.py", line 78, in handle_async_request
    stream = await self._connect(request)
             ^^^^^^^^^^^^^^^^^^^^^^^^^^^^
  File "D:\Programming\Python\Supp0rtBot\.venv\Lib\site-packages\httpcore\_async\connection.py", line 124, in _connect
    stream = await self._network_backend.connect_tcp(**kwargs)
             ^^^^^^^^^^^^^^^^^^^^^^^^^^^^^^^^^^^^^^^^^^^^^^^^^
  File "D:\Programming\Python\Supp0rtBot\.venv\Lib\site-packages\httpcore\_backends\auto.py", line 31, in connect_tcp
    return await self._backend.connect_tcp(
           ^^^^^^^^^^^^^^^^^^^^^^^^^^^^^^^^
  File "D:\Programming\Python\Supp0rtBot\.venv\Lib\site-packages\httpcore\_backends\anyio.py", line 113, in connect_tcp
    with map_exceptions(exc_map):
  File "C:\Users\38066\AppData\Local\Programs\Python\Python312\Lib\contextlib.py", line 158, in __exit__
    self.gen.throw(value)
  File "D:\Programming\Python\Supp0rtBot\.venv\Lib\site-packages\httpcore\_exceptions.py", line 14, in map_exceptions
    raise to_exc(exc) from exc
httpcore.ConnectError: [Errno 11001] getaddrinfo failed

The above exception was the direct cause of the following exception:

Traceback (most recent call last):
  File "D:\Programming\Python\Supp0rtBot\.venv\Lib\site-packages\telegram\request\_httpxrequest.py", line 293, in do_request
    res = await self._client.request(
          ^^^^^^^^^^^^^^^^^^^^^^^^^^^
  File "D:\Programming\Python\Supp0rtBot\.venv\Lib\site-packages\httpx\_client.py", line 1540, in request
    return await self.send(request, auth=auth, follow_redirects=follow_redirects)
           ^^^^^^^^^^^^^^^^^^^^^^^^^^^^^^^^^^^^^^^^^^^^^^^^^^^^^^^^^^^^^^^^^^^^^^
  File "D:\Programming\Python\Supp0rtBot\.venv\Lib\site-packages\httpx\_client.py", line 1629, in send
    response = await self._send_handling_auth(
               ^^^^^^^^^^^^^^^^^^^^^^^^^^^^^^^
  File "D:\Programming\Python\Supp0rtBot\.venv\Lib\site-packages\httpx\_client.py", line 1657, in _send_handling_auth
    response = await self._send_handling_redirects(
               ^^^^^^^^^^^^^^^^^^^^^^^^^^^^^^^^^^^^
  File "D:\Programming\Python\Supp0rtBot\.venv\Lib\site-packages\httpx\_client.py", line 1694, in _send_handling_redirects
    response = await self._send_single_request(request)
               ^^^^^^^^^^^^^^^^^^^^^^^^^^^^^^^^^^^^^^^^
  File "D:\Programming\Python\Supp0rtBot\.venv\Lib\site-packages\httpx\_client.py", line 1730, in _send_single_request
    response = await transport.handle_async_request(request)
               ^^^^^^^^^^^^^^^^^^^^^^^^^^^^^^^^^^^^^^^^^^^^^
  File "D:\Programming\Python\Supp0rtBot\.venv\Lib\site-packages\httpx\_transports\default.py", line 393, in handle_async_request
    with map_httpcore_exceptions():
  File "C:\Users\38066\AppData\Local\Programs\Python\Python312\Lib\contextlib.py", line 158, in __exit__
    self.gen.throw(value)
  File "D:\Programming\Python\Supp0rtBot\.venv\Lib\site-packages\httpx\_transports\default.py", line 118, in map_httpcore_exceptions
    raise mapped_exc(message) from exc
httpx.ConnectError: [Errno 11001] getaddrinfo failed

The above exception was the direct cause of the following exception:

Traceback (most recent call last):
  File "D:\Programming\Python\Supp0rtBot\.venv\Lib\site-packages\telegram\ext\_updater.py", line 750, in _network_loop_retry
    if not await do_action():
           ^^^^^^^^^^^^^^^^^
  File "D:\Programming\Python\Supp0rtBot\.venv\Lib\site-packages\telegram\ext\_updater.py", line 744, in do_action
    return action_cb_task.result()
           ^^^^^^^^^^^^^^^^^^^^^^^
  File "C:\Users\38066\AppData\Local\Programs\Python\Python312\Lib\asyncio\futures.py", line 203, in result
    raise self._exception.with_traceback(self._exception_tb)
  File "C:\Users\38066\AppData\Local\Programs\Python\Python312\Lib\asyncio\tasks.py", line 316, in __step_run_and_handle_result
    result = coro.throw(exc)
             ^^^^^^^^^^^^^^^
  File "D:\Programming\Python\Supp0rtBot\.venv\Lib\site-packages\telegram\ext\_updater.py", line 371, in polling_action_cb
    updates = await self.bot.get_updates(
              ^^^^^^^^^^^^^^^^^^^^^^^^^^^
  File "D:\Programming\Python\Supp0rtBot\.venv\Lib\site-packages\telegram\ext\_extbot.py", line 650, in get_updates
    updates = await super().get_updates(
              ^^^^^^^^^^^^^^^^^^^^^^^^^^
  File "D:\Programming\Python\Supp0rtBot\.venv\Lib\site-packages\telegram\_bot.py", line 4480, in get_updates
    await self._post(
  File "D:\Programming\Python\Supp0rtBot\.venv\Lib\site-packages\telegram\_bot.py", line 619, in _post
    return await self._do_post(
           ^^^^^^^^^^^^^^^^^^^^
  File "D:\Programming\Python\Supp0rtBot\.venv\Lib\site-packages\telegram\ext\_extbot.py", line 354, in _do_post
    return await super()._do_post(
           ^^^^^^^^^^^^^^^^^^^^^^^
  File "D:\Programming\Python\Supp0rtBot\.venv\Lib\site-packages\telegram\_bot.py", line 648, in _do_post
    result = await request.post(
             ^^^^^^^^^^^^^^^^^^^
  File "D:\Programming\Python\Supp0rtBot\.venv\Lib\site-packages\telegram\request\_baserequest.py", line 202, in post
    result = await self._request_wrapper(
             ^^^^^^^^^^^^^^^^^^^^^^^^^^^^
  File "D:\Programming\Python\Supp0rtBot\.venv\Lib\site-packages\telegram\request\_baserequest.py", line 334, in _request_wrapper
    code, payload = await self.do_request(
                    ^^^^^^^^^^^^^^^^^^^^^^
  File "D:\Programming\Python\Supp0rtBot\.venv\Lib\site-packages\telegram\request\_httpxrequest.py", line 317, in do_request
    raise NetworkError(f"httpx.{err.__class__.__name__}: {err}") from err
telegram.error.NetworkError: httpx.ConnectError: [Errno 11001] getaddrinfo failed
2025-05-17 10:38:05,112 - werkzeug - INFO - [31m[1mWARNING: This is a development server. Do not use it in a production deployment. Use a production WSGI server instead.[0m
 * Running on all addresses (0.0.0.0)
 * Running on http://127.0.0.1:5000
 * Running on http://192.168.31.105:5000
2025-05-17 10:38:05,113 - werkzeug - INFO - [33mPress CTRL+C to quit[0m
2025-05-17 10:58:09,752 - werkzeug - INFO - [31m[1mWARNING: This is a development server. Do not use it in a production deployment. Use a production WSGI server instead.[0m
 * Running on all addresses (0.0.0.0)
 * Running on http://127.0.0.1:5000
 * Running on http://192.168.31.105:5000
2025-05-17 10:58:09,752 - werkzeug - INFO - [33mPress CTRL+C to quit[0m
2025-05-17 11:17:26,410 - werkzeug - INFO - [31m[1mWARNING: This is a development server. Do not use it in a production deployment. Use a production WSGI server instead.[0m
 * Running on all addresses (0.0.0.0)
 * Running on http://127.0.0.1:5000
 * Running on http://192.168.31.105:5000
2025-05-17 11:17:26,410 - werkzeug - INFO - [33mPress CTRL+C to quit[0m
2025-05-17 16:19:34,000 - werkzeug - INFO - [31m[1mWARNING: This is a development server. Do not use it in a production deployment. Use a production WSGI server instead.[0m
 * Running on all addresses (0.0.0.0)
 * Running on http://127.0.0.1:5000
 * Running on http://192.168.31.105:5000
2025-05-17 16:19:34,028 - werkzeug - INFO - [33mPress CTRL+C to quit[0m
2025-05-17 16:21:19,503 - werkzeug - INFO - [31m[1mWARNING: This is a development server. Do not use it in a production deployment. Use a production WSGI server instead.[0m
 * Running on all addresses (0.0.0.0)
 * Running on http://127.0.0.1:5000
 * Running on http://192.168.31.105:5000
2025-05-17 16:21:19,504 - werkzeug - INFO - [33mPress CTRL+C to quit[0m
2025-05-17 16:26:28,973 - werkzeug - INFO - [31m[1mWARNING: This is a development server. Do not use it in a production deployment. Use a production WSGI server instead.[0m
 * Running on all addresses (0.0.0.0)
 * Running on http://127.0.0.1:5000
 * Running on http://192.168.31.105:5000
2025-05-17 16:26:28,973 - werkzeug - INFO - [33mPress CTRL+C to quit[0m
2025-05-17 16:27:27,354 - werkzeug - INFO - [31m[1mWARNING: This is a development server. Do not use it in a production deployment. Use a production WSGI server instead.[0m
 * Running on all addresses (0.0.0.0)
 * Running on http://127.0.0.1:5000
 * Running on http://192.168.31.105:5000
2025-05-17 16:27:27,354 - werkzeug - INFO - [33mPress CTRL+C to quit[0m
2025-05-17 16:30:20,004 - werkzeug - INFO - [31m[1mWARNING: This is a development server. Do not use it in a production deployment. Use a production WSGI server instead.[0m
 * Running on all addresses (0.0.0.0)
 * Running on http://127.0.0.1:5000
 * Running on http://192.168.31.105:5000
2025-05-17 16:30:20,004 - werkzeug - INFO - [33mPress CTRL+C to quit[0m
2025-05-17 16:42:54,396 - werkzeug - INFO - [31m[1mWARNING: This is a development server. Do not use it in a production deployment. Use a production WSGI server instead.[0m
 * Running on all addresses (0.0.0.0)
 * Running on http://127.0.0.1:5000
 * Running on http://192.168.31.105:5000
2025-05-17 16:42:54,396 - werkzeug - INFO - [33mPress CTRL+C to quit[0m
2025-05-17 17:33:15,909 - werkzeug - INFO - [31m[1mWARNING: This is a development server. Do not use it in a production deployment. Use a production WSGI server instead.[0m
 * Running on all addresses (0.0.0.0)
 * Running on http://127.0.0.1:5000
 * Running on http://192.168.31.105:5000
2025-05-17 17:33:15,909 - werkzeug - INFO - [33mPress CTRL+C to quit[0m
2025-05-17 17:33:57,373 - werkzeug - INFO - [31m[1mWARNING: This is a development server. Do not use it in a production deployment. Use a production WSGI server instead.[0m
 * Running on all addresses (0.0.0.0)
 * Running on http://127.0.0.1:5000
 * Running on http://192.168.31.105:5000
2025-05-17 17:33:57,374 - werkzeug - INFO - [33mPress CTRL+C to quit[0m
2025-05-17 18:07:32,960 - werkzeug - INFO - [31m[1mWARNING: This is a development server. Do not use it in a production deployment. Use a production WSGI server instead.[0m
 * Running on all addresses (0.0.0.0)
 * Running on http://127.0.0.1:5000
 * Running on http://192.168.31.105:5000
2025-05-17 18:07:32,961 - werkzeug - INFO - [33mPress CTRL+C to quit[0m
2025-05-17 18:36:32,538 - werkzeug - INFO - [31m[1mWARNING: This is a development server. Do not use it in a production deployment. Use a production WSGI server instead.[0m
 * Running on all addresses (0.0.0.0)
 * Running on http://127.0.0.1:5000
 * Running on http://192.168.31.105:5000
2025-05-17 18:36:32,538 - werkzeug - INFO - [33mPress CTRL+C to quit[0m
2025-05-17 18:40:33,404 - werkzeug - INFO - [31m[1mWARNING: This is a development server. Do not use it in a production deployment. Use a production WSGI server instead.[0m
 * Running on all addresses (0.0.0.0)
 * Running on http://127.0.0.1:5000
 * Running on http://192.168.31.105:5000
2025-05-17 18:40:33,404 - werkzeug - INFO - [33mPress CTRL+C to quit[0m
2025-05-17 18:42:34,207 - werkzeug - INFO - [31m[1mWARNING: This is a development server. Do not use it in a production deployment. Use a production WSGI server instead.[0m
 * Running on all addresses (0.0.0.0)
 * Running on http://127.0.0.1:5000
 * Running on http://192.168.31.105:5000
2025-05-17 18:42:34,208 - werkzeug - INFO - [33mPress CTRL+C to quit[0m
2025-05-17 18:53:07,680 - werkzeug - INFO - [31m[1mWARNING: This is a development server. Do not use it in a production deployment. Use a production WSGI server instead.[0m
 * Running on all addresses (0.0.0.0)
 * Running on http://127.0.0.1:5000
 * Running on http://192.168.31.105:5000
2025-05-17 18:53:07,681 - werkzeug - INFO - [33mPress CTRL+C to quit[0m
2025-05-17 19:48:32,714 - werkzeug - INFO - [31m[1mWARNING: This is a development server. Do not use it in a production deployment. Use a production WSGI server instead.[0m
 * Running on all addresses (0.0.0.0)
 * Running on http://127.0.0.1:5000
 * Running on http://192.168.31.105:5000
2025-05-17 19:48:32,714 - werkzeug - INFO - [33mPress CTRL+C to quit[0m
2025-05-17 20:25:49,435 - werkzeug - INFO - [31m[1mWARNING: This is a development server. Do not use it in a production deployment. Use a production WSGI server instead.[0m
 * Running on all addresses (0.0.0.0)
 * Running on http://127.0.0.1:5000
 * Running on http://192.168.31.105:5000
2025-05-17 20:25:49,435 - werkzeug - INFO - [33mPress CTRL+C to quit[0m
2025-05-17 20:26:34,018 - werkzeug - INFO - [31m[1mWARNING: This is a development server. Do not use it in a production deployment. Use a production WSGI server instead.[0m
 * Running on all addresses (0.0.0.0)
 * Running on http://127.0.0.1:5000
 * Running on http://192.168.31.105:5000
2025-05-17 20:26:34,019 - werkzeug - INFO - [33mPress CTRL+C to quit[0m
2025-05-17 20:31:41,969 - werkzeug - INFO - [31m[1mWARNING: This is a development server. Do not use it in a production deployment. Use a production WSGI server instead.[0m
 * Running on all addresses (0.0.0.0)
 * Running on http://127.0.0.1:5000
 * Running on http://192.168.31.105:5000
2025-05-17 20:31:41,970 - werkzeug - INFO - [33mPress CTRL+C to quit[0m
2025-05-17 20:32:27,595 - werkzeug - INFO - [31m[1mWARNING: This is a development server. Do not use it in a production deployment. Use a production WSGI server instead.[0m
 * Running on all addresses (0.0.0.0)
 * Running on http://127.0.0.1:5000
 * Running on http://192.168.31.105:5000
2025-05-17 20:32:27,598 - werkzeug - INFO - [33mPress CTRL+C to quit[0m
2025-05-17 20:33:54,350 - werkzeug - INFO - 192.168.31.105 - - [17/May/2025 20:33:54] "GET / HTTP/1.1" 200 -
2025-05-17 20:34:00,849 - werkzeug - INFO - 192.168.31.105 - - [17/May/2025 20:34:00] "[31m[1mGET / HTTP/1.1[0m" 400 -
2025-05-17 20:34:00,881 - werkzeug - INFO - 192.168.31.105 - - [17/May/2025 20:34:00] "[33mGET /loginMsg.js HTTP/1.1[0m" 404 -
2025-05-17 20:34:00,902 - werkzeug - INFO - 192.168.31.105 - - [17/May/2025 20:34:00] "[33mGET /cgi/get.cgi?cmd=home_login HTTP/1.1[0m" 404 -
2025-05-17 20:34:02,149 - werkzeug - INFO - 192.168.31.105 - - [17/May/2025 20:34:02] "[33mGET /rootDesc.xml HTTP/1.1[0m" 404 -
2025-05-17 20:35:44,387 - werkzeug - INFO - [31m[1mWARNING: This is a development server. Do not use it in a production deployment. Use a production WSGI server instead.[0m
 * Running on all addresses (0.0.0.0)
 * Running on http://127.0.0.1:5000
 * Running on http://192.168.31.105:5000
2025-05-17 20:35:44,387 - werkzeug - INFO - [33mPress CTRL+C to quit[0m
2025-05-17 20:38:50,460 - werkzeug - INFO - [31m[1mWARNING: This is a development server. Do not use it in a production deployment. Use a production WSGI server instead.[0m
 * Running on all addresses (0.0.0.0)
 * Running on http://127.0.0.1:5000
 * Running on http://192.168.31.105:5000
2025-05-17 20:38:50,460 - werkzeug - INFO - [33mPress CTRL+C to quit[0m
2025-05-17 20:42:10,096 - werkzeug - INFO - [31m[1mWARNING: This is a development server. Do not use it in a production deployment. Use a production WSGI server instead.[0m
 * Running on all addresses (0.0.0.0)
 * Running on http://127.0.0.1:5000
 * Running on http://192.168.31.105:5000
2025-05-17 20:42:10,097 - werkzeug - INFO - [33mPress CTRL+C to quit[0m
2025-05-17 22:39:34,099 - werkzeug - INFO - [31m[1mWARNING: This is a development server. Do not use it in a production deployment. Use a production WSGI server instead.[0m
 * Running on all addresses (0.0.0.0)
 * Running on http://127.0.0.1:5000
 * Running on http://192.168.31.105:5000
2025-05-17 22:39:34,099 - werkzeug - INFO - [33mPress CTRL+C to quit[0m
2025-05-17 22:42:12,688 - werkzeug - INFO - [31m[1mWARNING: This is a development server. Do not use it in a production deployment. Use a production WSGI server instead.[0m
 * Running on all addresses (0.0.0.0)
 * Running on http://127.0.0.1:5000
 * Running on http://192.168.31.105:5000
2025-05-17 22:42:12,689 - werkzeug - INFO - [33mPress CTRL+C to quit[0m
2025-05-17 22:42:50,711 - werkzeug - INFO - [31m[1mWARNING: This is a development server. Do not use it in a production deployment. Use a production WSGI server instead.[0m
 * Running on all addresses (0.0.0.0)
 * Running on http://127.0.0.1:5000
 * Running on http://192.168.31.105:5000
2025-05-17 22:42:50,712 - werkzeug - INFO - [33mPress CTRL+C to quit[0m
2025-05-17 23:00:25,238 - telegram.ext.Application - ERROR - No error handlers are registered, logging exception.
Traceback (most recent call last):
  File "D:\Programming\Python\Supp0rtBot\.venv\Lib\site-packages\httpx\_transports\default.py", line 101, in map_httpcore_exceptions
    yield
  File "D:\Programming\Python\Supp0rtBot\.venv\Lib\site-packages\httpx\_transports\default.py", line 394, in handle_async_request
    resp = await self._pool.handle_async_request(req)
           ^^^^^^^^^^^^^^^^^^^^^^^^^^^^^^^^^^^^^^^^^^
  File "D:\Programming\Python\Supp0rtBot\.venv\Lib\site-packages\httpcore\_async\connection_pool.py", line 256, in handle_async_request
    raise exc from None
  File "D:\Programming\Python\Supp0rtBot\.venv\Lib\site-packages\httpcore\_async\connection_pool.py", line 236, in handle_async_request
    response = await connection.handle_async_request(
               ^^^^^^^^^^^^^^^^^^^^^^^^^^^^^^^^^^^^^^
  File "D:\Programming\Python\Supp0rtBot\.venv\Lib\site-packages\httpcore\_async\connection.py", line 101, in handle_async_request
    raise exc
  File "D:\Programming\Python\Supp0rtBot\.venv\Lib\site-packages\httpcore\_async\connection.py", line 78, in handle_async_request
    stream = await self._connect(request)
             ^^^^^^^^^^^^^^^^^^^^^^^^^^^^
  File "D:\Programming\Python\Supp0rtBot\.venv\Lib\site-packages\httpcore\_async\connection.py", line 124, in _connect
    stream = await self._network_backend.connect_tcp(**kwargs)
             ^^^^^^^^^^^^^^^^^^^^^^^^^^^^^^^^^^^^^^^^^^^^^^^^^
  File "D:\Programming\Python\Supp0rtBot\.venv\Lib\site-packages\httpcore\_backends\auto.py", line 31, in connect_tcp
    return await self._backend.connect_tcp(
           ^^^^^^^^^^^^^^^^^^^^^^^^^^^^^^^^
  File "D:\Programming\Python\Supp0rtBot\.venv\Lib\site-packages\httpcore\_backends\anyio.py", line 113, in connect_tcp
    with map_exceptions(exc_map):
  File "C:\Users\38066\AppData\Local\Programs\Python\Python312\Lib\contextlib.py", line 158, in __exit__
    self.gen.throw(value)
  File "D:\Programming\Python\Supp0rtBot\.venv\Lib\site-packages\httpcore\_exceptions.py", line 14, in map_exceptions
    raise to_exc(exc) from exc
httpcore.ConnectError: [Errno 11001] getaddrinfo failed

The above exception was the direct cause of the following exception:

Traceback (most recent call last):
  File "D:\Programming\Python\Supp0rtBot\.venv\Lib\site-packages\telegram\request\_httpxrequest.py", line 293, in do_request
    res = await self._client.request(
          ^^^^^^^^^^^^^^^^^^^^^^^^^^^
  File "D:\Programming\Python\Supp0rtBot\.venv\Lib\site-packages\httpx\_client.py", line 1540, in request
    return await self.send(request, auth=auth, follow_redirects=follow_redirects)
           ^^^^^^^^^^^^^^^^^^^^^^^^^^^^^^^^^^^^^^^^^^^^^^^^^^^^^^^^^^^^^^^^^^^^^^
  File "D:\Programming\Python\Supp0rtBot\.venv\Lib\site-packages\httpx\_client.py", line 1629, in send
    response = await self._send_handling_auth(
               ^^^^^^^^^^^^^^^^^^^^^^^^^^^^^^^
  File "D:\Programming\Python\Supp0rtBot\.venv\Lib\site-packages\httpx\_client.py", line 1657, in _send_handling_auth
    response = await self._send_handling_redirects(
               ^^^^^^^^^^^^^^^^^^^^^^^^^^^^^^^^^^^^
  File "D:\Programming\Python\Supp0rtBot\.venv\Lib\site-packages\httpx\_client.py", line 1694, in _send_handling_redirects
    response = await self._send_single_request(request)
               ^^^^^^^^^^^^^^^^^^^^^^^^^^^^^^^^^^^^^^^^
  File "D:\Programming\Python\Supp0rtBot\.venv\Lib\site-packages\httpx\_client.py", line 1730, in _send_single_request
    response = await transport.handle_async_request(request)
               ^^^^^^^^^^^^^^^^^^^^^^^^^^^^^^^^^^^^^^^^^^^^^
  File "D:\Programming\Python\Supp0rtBot\.venv\Lib\site-packages\httpx\_transports\default.py", line 393, in handle_async_request
    with map_httpcore_exceptions():
  File "C:\Users\38066\AppData\Local\Programs\Python\Python312\Lib\contextlib.py", line 158, in __exit__
    self.gen.throw(value)
  File "D:\Programming\Python\Supp0rtBot\.venv\Lib\site-packages\httpx\_transports\default.py", line 118, in map_httpcore_exceptions
    raise mapped_exc(message) from exc
httpx.ConnectError: [Errno 11001] getaddrinfo failed

The above exception was the direct cause of the following exception:

Traceback (most recent call last):
  File "D:\Programming\Python\Supp0rtBot\.venv\Lib\site-packages\telegram\ext\_updater.py", line 750, in _network_loop_retry
    if not await do_action():
           ^^^^^^^^^^^^^^^^^
  File "D:\Programming\Python\Supp0rtBot\.venv\Lib\site-packages\telegram\ext\_updater.py", line 744, in do_action
    return action_cb_task.result()
           ^^^^^^^^^^^^^^^^^^^^^^^
  File "C:\Users\38066\AppData\Local\Programs\Python\Python312\Lib\asyncio\futures.py", line 203, in result
    raise self._exception.with_traceback(self._exception_tb)
  File "C:\Users\38066\AppData\Local\Programs\Python\Python312\Lib\asyncio\tasks.py", line 316, in __step_run_and_handle_result
    result = coro.throw(exc)
             ^^^^^^^^^^^^^^^
  File "D:\Programming\Python\Supp0rtBot\.venv\Lib\site-packages\telegram\ext\_updater.py", line 371, in polling_action_cb
    updates = await self.bot.get_updates(
              ^^^^^^^^^^^^^^^^^^^^^^^^^^^
  File "D:\Programming\Python\Supp0rtBot\.venv\Lib\site-packages\telegram\ext\_extbot.py", line 650, in get_updates
    updates = await super().get_updates(
              ^^^^^^^^^^^^^^^^^^^^^^^^^^
  File "D:\Programming\Python\Supp0rtBot\.venv\Lib\site-packages\telegram\_bot.py", line 4480, in get_updates
    await self._post(
  File "D:\Programming\Python\Supp0rtBot\.venv\Lib\site-packages\telegram\_bot.py", line 619, in _post
    return await self._do_post(
           ^^^^^^^^^^^^^^^^^^^^
  File "D:\Programming\Python\Supp0rtBot\.venv\Lib\site-packages\telegram\ext\_extbot.py", line 354, in _do_post
    return await super()._do_post(
           ^^^^^^^^^^^^^^^^^^^^^^^
  File "D:\Programming\Python\Supp0rtBot\.venv\Lib\site-packages\telegram\_bot.py", line 648, in _do_post
    result = await request.post(
             ^^^^^^^^^^^^^^^^^^^
  File "D:\Programming\Python\Supp0rtBot\.venv\Lib\site-packages\telegram\request\_baserequest.py", line 202, in post
    result = await self._request_wrapper(
             ^^^^^^^^^^^^^^^^^^^^^^^^^^^^
  File "D:\Programming\Python\Supp0rtBot\.venv\Lib\site-packages\telegram\request\_baserequest.py", line 334, in _request_wrapper
    code, payload = await self.do_request(
                    ^^^^^^^^^^^^^^^^^^^^^^
  File "D:\Programming\Python\Supp0rtBot\.venv\Lib\site-packages\telegram\request\_httpxrequest.py", line 317, in do_request
    raise NetworkError(f"httpx.{err.__class__.__name__}: {err}") from err
telegram.error.NetworkError: httpx.ConnectError: [Errno 11001] getaddrinfo failed
2025-05-17 23:00:26,263 - telegram.ext.Application - ERROR - No error handlers are registered, logging exception.
Traceback (most recent call last):
  File "D:\Programming\Python\Supp0rtBot\.venv\Lib\site-packages\httpx\_transports\default.py", line 101, in map_httpcore_exceptions
    yield
  File "D:\Programming\Python\Supp0rtBot\.venv\Lib\site-packages\httpx\_transports\default.py", line 394, in handle_async_request
    resp = await self._pool.handle_async_request(req)
           ^^^^^^^^^^^^^^^^^^^^^^^^^^^^^^^^^^^^^^^^^^
  File "D:\Programming\Python\Supp0rtBot\.venv\Lib\site-packages\httpcore\_async\connection_pool.py", line 256, in handle_async_request
    raise exc from None
  File "D:\Programming\Python\Supp0rtBot\.venv\Lib\site-packages\httpcore\_async\connection_pool.py", line 236, in handle_async_request
    response = await connection.handle_async_request(
               ^^^^^^^^^^^^^^^^^^^^^^^^^^^^^^^^^^^^^^
  File "D:\Programming\Python\Supp0rtBot\.venv\Lib\site-packages\httpcore\_async\connection.py", line 101, in handle_async_request
    raise exc
  File "D:\Programming\Python\Supp0rtBot\.venv\Lib\site-packages\httpcore\_async\connection.py", line 78, in handle_async_request
    stream = await self._connect(request)
             ^^^^^^^^^^^^^^^^^^^^^^^^^^^^
  File "D:\Programming\Python\Supp0rtBot\.venv\Lib\site-packages\httpcore\_async\connection.py", line 124, in _connect
    stream = await self._network_backend.connect_tcp(**kwargs)
             ^^^^^^^^^^^^^^^^^^^^^^^^^^^^^^^^^^^^^^^^^^^^^^^^^
  File "D:\Programming\Python\Supp0rtBot\.venv\Lib\site-packages\httpcore\_backends\auto.py", line 31, in connect_tcp
    return await self._backend.connect_tcp(
           ^^^^^^^^^^^^^^^^^^^^^^^^^^^^^^^^
  File "D:\Programming\Python\Supp0rtBot\.venv\Lib\site-packages\httpcore\_backends\anyio.py", line 113, in connect_tcp
    with map_exceptions(exc_map):
  File "C:\Users\38066\AppData\Local\Programs\Python\Python312\Lib\contextlib.py", line 158, in __exit__
    self.gen.throw(value)
  File "D:\Programming\Python\Supp0rtBot\.venv\Lib\site-packages\httpcore\_exceptions.py", line 14, in map_exceptions
    raise to_exc(exc) from exc
httpcore.ConnectError: [Errno 11001] getaddrinfo failed

The above exception was the direct cause of the following exception:

Traceback (most recent call last):
  File "D:\Programming\Python\Supp0rtBot\.venv\Lib\site-packages\telegram\request\_httpxrequest.py", line 293, in do_request
    res = await self._client.request(
          ^^^^^^^^^^^^^^^^^^^^^^^^^^^
  File "D:\Programming\Python\Supp0rtBot\.venv\Lib\site-packages\httpx\_client.py", line 1540, in request
    return await self.send(request, auth=auth, follow_redirects=follow_redirects)
           ^^^^^^^^^^^^^^^^^^^^^^^^^^^^^^^^^^^^^^^^^^^^^^^^^^^^^^^^^^^^^^^^^^^^^^
  File "D:\Programming\Python\Supp0rtBot\.venv\Lib\site-packages\httpx\_client.py", line 1629, in send
    response = await self._send_handling_auth(
               ^^^^^^^^^^^^^^^^^^^^^^^^^^^^^^^
  File "D:\Programming\Python\Supp0rtBot\.venv\Lib\site-packages\httpx\_client.py", line 1657, in _send_handling_auth
    response = await self._send_handling_redirects(
               ^^^^^^^^^^^^^^^^^^^^^^^^^^^^^^^^^^^^
  File "D:\Programming\Python\Supp0rtBot\.venv\Lib\site-packages\httpx\_client.py", line 1694, in _send_handling_redirects
    response = await self._send_single_request(request)
               ^^^^^^^^^^^^^^^^^^^^^^^^^^^^^^^^^^^^^^^^
  File "D:\Programming\Python\Supp0rtBot\.venv\Lib\site-packages\httpx\_client.py", line 1730, in _send_single_request
    response = await transport.handle_async_request(request)
               ^^^^^^^^^^^^^^^^^^^^^^^^^^^^^^^^^^^^^^^^^^^^^
  File "D:\Programming\Python\Supp0rtBot\.venv\Lib\site-packages\httpx\_transports\default.py", line 393, in handle_async_request
    with map_httpcore_exceptions():
  File "C:\Users\38066\AppData\Local\Programs\Python\Python312\Lib\contextlib.py", line 158, in __exit__
    self.gen.throw(value)
  File "D:\Programming\Python\Supp0rtBot\.venv\Lib\site-packages\httpx\_transports\default.py", line 118, in map_httpcore_exceptions
    raise mapped_exc(message) from exc
httpx.ConnectError: [Errno 11001] getaddrinfo failed

The above exception was the direct cause of the following exception:

Traceback (most recent call last):
  File "D:\Programming\Python\Supp0rtBot\.venv\Lib\site-packages\telegram\ext\_updater.py", line 750, in _network_loop_retry
    if not await do_action():
           ^^^^^^^^^^^^^^^^^
  File "D:\Programming\Python\Supp0rtBot\.venv\Lib\site-packages\telegram\ext\_updater.py", line 744, in do_action
    return action_cb_task.result()
           ^^^^^^^^^^^^^^^^^^^^^^^
  File "C:\Users\38066\AppData\Local\Programs\Python\Python312\Lib\asyncio\futures.py", line 203, in result
    raise self._exception.with_traceback(self._exception_tb)
  File "C:\Users\38066\AppData\Local\Programs\Python\Python312\Lib\asyncio\tasks.py", line 316, in __step_run_and_handle_result
    result = coro.throw(exc)
             ^^^^^^^^^^^^^^^
  File "D:\Programming\Python\Supp0rtBot\.venv\Lib\site-packages\telegram\ext\_updater.py", line 371, in polling_action_cb
    updates = await self.bot.get_updates(
              ^^^^^^^^^^^^^^^^^^^^^^^^^^^
  File "D:\Programming\Python\Supp0rtBot\.venv\Lib\site-packages\telegram\ext\_extbot.py", line 650, in get_updates
    updates = await super().get_updates(
              ^^^^^^^^^^^^^^^^^^^^^^^^^^
  File "D:\Programming\Python\Supp0rtBot\.venv\Lib\site-packages\telegram\_bot.py", line 4480, in get_updates
    await self._post(
  File "D:\Programming\Python\Supp0rtBot\.venv\Lib\site-packages\telegram\_bot.py", line 619, in _post
    return await self._do_post(
           ^^^^^^^^^^^^^^^^^^^^
  File "D:\Programming\Python\Supp0rtBot\.venv\Lib\site-packages\telegram\ext\_extbot.py", line 354, in _do_post
    return await super()._do_post(
           ^^^^^^^^^^^^^^^^^^^^^^^
  File "D:\Programming\Python\Supp0rtBot\.venv\Lib\site-packages\telegram\_bot.py", line 648, in _do_post
    result = await request.post(
             ^^^^^^^^^^^^^^^^^^^
  File "D:\Programming\Python\Supp0rtBot\.venv\Lib\site-packages\telegram\request\_baserequest.py", line 202, in post
    result = await self._request_wrapper(
             ^^^^^^^^^^^^^^^^^^^^^^^^^^^^
  File "D:\Programming\Python\Supp0rtBot\.venv\Lib\site-packages\telegram\request\_baserequest.py", line 334, in _request_wrapper
    code, payload = await self.do_request(
                    ^^^^^^^^^^^^^^^^^^^^^^
  File "D:\Programming\Python\Supp0rtBot\.venv\Lib\site-packages\telegram\request\_httpxrequest.py", line 317, in do_request
    raise NetworkError(f"httpx.{err.__class__.__name__}: {err}") from err
telegram.error.NetworkError: httpx.ConnectError: [Errno 11001] getaddrinfo failed
2025-05-17 23:00:27,786 - telegram.ext.Application - ERROR - No error handlers are registered, logging exception.
Traceback (most recent call last):
  File "D:\Programming\Python\Supp0rtBot\.venv\Lib\site-packages\httpx\_transports\default.py", line 101, in map_httpcore_exceptions
    yield
  File "D:\Programming\Python\Supp0rtBot\.venv\Lib\site-packages\httpx\_transports\default.py", line 394, in handle_async_request
    resp = await self._pool.handle_async_request(req)
           ^^^^^^^^^^^^^^^^^^^^^^^^^^^^^^^^^^^^^^^^^^
  File "D:\Programming\Python\Supp0rtBot\.venv\Lib\site-packages\httpcore\_async\connection_pool.py", line 256, in handle_async_request
    raise exc from None
  File "D:\Programming\Python\Supp0rtBot\.venv\Lib\site-packages\httpcore\_async\connection_pool.py", line 236, in handle_async_request
    response = await connection.handle_async_request(
               ^^^^^^^^^^^^^^^^^^^^^^^^^^^^^^^^^^^^^^
  File "D:\Programming\Python\Supp0rtBot\.venv\Lib\site-packages\httpcore\_async\connection.py", line 101, in handle_async_request
    raise exc
  File "D:\Programming\Python\Supp0rtBot\.venv\Lib\site-packages\httpcore\_async\connection.py", line 78, in handle_async_request
    stream = await self._connect(request)
             ^^^^^^^^^^^^^^^^^^^^^^^^^^^^
  File "D:\Programming\Python\Supp0rtBot\.venv\Lib\site-packages\httpcore\_async\connection.py", line 124, in _connect
    stream = await self._network_backend.connect_tcp(**kwargs)
             ^^^^^^^^^^^^^^^^^^^^^^^^^^^^^^^^^^^^^^^^^^^^^^^^^
  File "D:\Programming\Python\Supp0rtBot\.venv\Lib\site-packages\httpcore\_backends\auto.py", line 31, in connect_tcp
    return await self._backend.connect_tcp(
           ^^^^^^^^^^^^^^^^^^^^^^^^^^^^^^^^
  File "D:\Programming\Python\Supp0rtBot\.venv\Lib\site-packages\httpcore\_backends\anyio.py", line 113, in connect_tcp
    with map_exceptions(exc_map):
  File "C:\Users\38066\AppData\Local\Programs\Python\Python312\Lib\contextlib.py", line 158, in __exit__
    self.gen.throw(value)
  File "D:\Programming\Python\Supp0rtBot\.venv\Lib\site-packages\httpcore\_exceptions.py", line 14, in map_exceptions
    raise to_exc(exc) from exc
httpcore.ConnectError: [Errno 11001] getaddrinfo failed

The above exception was the direct cause of the following exception:

Traceback (most recent call last):
  File "D:\Programming\Python\Supp0rtBot\.venv\Lib\site-packages\telegram\request\_httpxrequest.py", line 293, in do_request
    res = await self._client.request(
          ^^^^^^^^^^^^^^^^^^^^^^^^^^^
  File "D:\Programming\Python\Supp0rtBot\.venv\Lib\site-packages\httpx\_client.py", line 1540, in request
    return await self.send(request, auth=auth, follow_redirects=follow_redirects)
           ^^^^^^^^^^^^^^^^^^^^^^^^^^^^^^^^^^^^^^^^^^^^^^^^^^^^^^^^^^^^^^^^^^^^^^
  File "D:\Programming\Python\Supp0rtBot\.venv\Lib\site-packages\httpx\_client.py", line 1629, in send
    response = await self._send_handling_auth(
               ^^^^^^^^^^^^^^^^^^^^^^^^^^^^^^^
  File "D:\Programming\Python\Supp0rtBot\.venv\Lib\site-packages\httpx\_client.py", line 1657, in _send_handling_auth
    response = await self._send_handling_redirects(
               ^^^^^^^^^^^^^^^^^^^^^^^^^^^^^^^^^^^^
  File "D:\Programming\Python\Supp0rtBot\.venv\Lib\site-packages\httpx\_client.py", line 1694, in _send_handling_redirects
    response = await self._send_single_request(request)
               ^^^^^^^^^^^^^^^^^^^^^^^^^^^^^^^^^^^^^^^^
  File "D:\Programming\Python\Supp0rtBot\.venv\Lib\site-packages\httpx\_client.py", line 1730, in _send_single_request
    response = await transport.handle_async_request(request)
               ^^^^^^^^^^^^^^^^^^^^^^^^^^^^^^^^^^^^^^^^^^^^^
  File "D:\Programming\Python\Supp0rtBot\.venv\Lib\site-packages\httpx\_transports\default.py", line 393, in handle_async_request
    with map_httpcore_exceptions():
  File "C:\Users\38066\AppData\Local\Programs\Python\Python312\Lib\contextlib.py", line 158, in __exit__
    self.gen.throw(value)
  File "D:\Programming\Python\Supp0rtBot\.venv\Lib\site-packages\httpx\_transports\default.py", line 118, in map_httpcore_exceptions
    raise mapped_exc(message) from exc
httpx.ConnectError: [Errno 11001] getaddrinfo failed

The above exception was the direct cause of the following exception:

Traceback (most recent call last):
  File "D:\Programming\Python\Supp0rtBot\.venv\Lib\site-packages\telegram\ext\_updater.py", line 750, in _network_loop_retry
    if not await do_action():
           ^^^^^^^^^^^^^^^^^
  File "D:\Programming\Python\Supp0rtBot\.venv\Lib\site-packages\telegram\ext\_updater.py", line 744, in do_action
    return action_cb_task.result()
           ^^^^^^^^^^^^^^^^^^^^^^^
  File "C:\Users\38066\AppData\Local\Programs\Python\Python312\Lib\asyncio\futures.py", line 203, in result
    raise self._exception.with_traceback(self._exception_tb)
  File "C:\Users\38066\AppData\Local\Programs\Python\Python312\Lib\asyncio\tasks.py", line 316, in __step_run_and_handle_result
    result = coro.throw(exc)
             ^^^^^^^^^^^^^^^
  File "D:\Programming\Python\Supp0rtBot\.venv\Lib\site-packages\telegram\ext\_updater.py", line 371, in polling_action_cb
    updates = await self.bot.get_updates(
              ^^^^^^^^^^^^^^^^^^^^^^^^^^^
  File "D:\Programming\Python\Supp0rtBot\.venv\Lib\site-packages\telegram\ext\_extbot.py", line 650, in get_updates
    updates = await super().get_updates(
              ^^^^^^^^^^^^^^^^^^^^^^^^^^
  File "D:\Programming\Python\Supp0rtBot\.venv\Lib\site-packages\telegram\_bot.py", line 4480, in get_updates
    await self._post(
  File "D:\Programming\Python\Supp0rtBot\.venv\Lib\site-packages\telegram\_bot.py", line 619, in _post
    return await self._do_post(
           ^^^^^^^^^^^^^^^^^^^^
  File "D:\Programming\Python\Supp0rtBot\.venv\Lib\site-packages\telegram\ext\_extbot.py", line 354, in _do_post
    return await super()._do_post(
           ^^^^^^^^^^^^^^^^^^^^^^^
  File "D:\Programming\Python\Supp0rtBot\.venv\Lib\site-packages\telegram\_bot.py", line 648, in _do_post
    result = await request.post(
             ^^^^^^^^^^^^^^^^^^^
  File "D:\Programming\Python\Supp0rtBot\.venv\Lib\site-packages\telegram\request\_baserequest.py", line 202, in post
    result = await self._request_wrapper(
             ^^^^^^^^^^^^^^^^^^^^^^^^^^^^
  File "D:\Programming\Python\Supp0rtBot\.venv\Lib\site-packages\telegram\request\_baserequest.py", line 334, in _request_wrapper
    code, payload = await self.do_request(
                    ^^^^^^^^^^^^^^^^^^^^^^
  File "D:\Programming\Python\Supp0rtBot\.venv\Lib\site-packages\telegram\request\_httpxrequest.py", line 317, in do_request
    raise NetworkError(f"httpx.{err.__class__.__name__}: {err}") from err
telegram.error.NetworkError: httpx.ConnectError: [Errno 11001] getaddrinfo failed
2025-05-17 23:00:30,051 - telegram.ext.Application - ERROR - No error handlers are registered, logging exception.
Traceback (most recent call last):
  File "D:\Programming\Python\Supp0rtBot\.venv\Lib\site-packages\httpx\_transports\default.py", line 101, in map_httpcore_exceptions
    yield
  File "D:\Programming\Python\Supp0rtBot\.venv\Lib\site-packages\httpx\_transports\default.py", line 394, in handle_async_request
    resp = await self._pool.handle_async_request(req)
           ^^^^^^^^^^^^^^^^^^^^^^^^^^^^^^^^^^^^^^^^^^
  File "D:\Programming\Python\Supp0rtBot\.venv\Lib\site-packages\httpcore\_async\connection_pool.py", line 256, in handle_async_request
    raise exc from None
  File "D:\Programming\Python\Supp0rtBot\.venv\Lib\site-packages\httpcore\_async\connection_pool.py", line 236, in handle_async_request
    response = await connection.handle_async_request(
               ^^^^^^^^^^^^^^^^^^^^^^^^^^^^^^^^^^^^^^
  File "D:\Programming\Python\Supp0rtBot\.venv\Lib\site-packages\httpcore\_async\connection.py", line 101, in handle_async_request
    raise exc
  File "D:\Programming\Python\Supp0rtBot\.venv\Lib\site-packages\httpcore\_async\connection.py", line 78, in handle_async_request
    stream = await self._connect(request)
             ^^^^^^^^^^^^^^^^^^^^^^^^^^^^
  File "D:\Programming\Python\Supp0rtBot\.venv\Lib\site-packages\httpcore\_async\connection.py", line 124, in _connect
    stream = await self._network_backend.connect_tcp(**kwargs)
             ^^^^^^^^^^^^^^^^^^^^^^^^^^^^^^^^^^^^^^^^^^^^^^^^^
  File "D:\Programming\Python\Supp0rtBot\.venv\Lib\site-packages\httpcore\_backends\auto.py", line 31, in connect_tcp
    return await self._backend.connect_tcp(
           ^^^^^^^^^^^^^^^^^^^^^^^^^^^^^^^^
  File "D:\Programming\Python\Supp0rtBot\.venv\Lib\site-packages\httpcore\_backends\anyio.py", line 113, in connect_tcp
    with map_exceptions(exc_map):
  File "C:\Users\38066\AppData\Local\Programs\Python\Python312\Lib\contextlib.py", line 158, in __exit__
    self.gen.throw(value)
  File "D:\Programming\Python\Supp0rtBot\.venv\Lib\site-packages\httpcore\_exceptions.py", line 14, in map_exceptions
    raise to_exc(exc) from exc
httpcore.ConnectError: [Errno 11001] getaddrinfo failed

The above exception was the direct cause of the following exception:

Traceback (most recent call last):
  File "D:\Programming\Python\Supp0rtBot\.venv\Lib\site-packages\telegram\request\_httpxrequest.py", line 293, in do_request
    res = await self._client.request(
          ^^^^^^^^^^^^^^^^^^^^^^^^^^^
  File "D:\Programming\Python\Supp0rtBot\.venv\Lib\site-packages\httpx\_client.py", line 1540, in request
    return await self.send(request, auth=auth, follow_redirects=follow_redirects)
           ^^^^^^^^^^^^^^^^^^^^^^^^^^^^^^^^^^^^^^^^^^^^^^^^^^^^^^^^^^^^^^^^^^^^^^
  File "D:\Programming\Python\Supp0rtBot\.venv\Lib\site-packages\httpx\_client.py", line 1629, in send
    response = await self._send_handling_auth(
               ^^^^^^^^^^^^^^^^^^^^^^^^^^^^^^^
  File "D:\Programming\Python\Supp0rtBot\.venv\Lib\site-packages\httpx\_client.py", line 1657, in _send_handling_auth
    response = await self._send_handling_redirects(
               ^^^^^^^^^^^^^^^^^^^^^^^^^^^^^^^^^^^^
  File "D:\Programming\Python\Supp0rtBot\.venv\Lib\site-packages\httpx\_client.py", line 1694, in _send_handling_redirects
    response = await self._send_single_request(request)
               ^^^^^^^^^^^^^^^^^^^^^^^^^^^^^^^^^^^^^^^^
  File "D:\Programming\Python\Supp0rtBot\.venv\Lib\site-packages\httpx\_client.py", line 1730, in _send_single_request
    response = await transport.handle_async_request(request)
               ^^^^^^^^^^^^^^^^^^^^^^^^^^^^^^^^^^^^^^^^^^^^^
  File "D:\Programming\Python\Supp0rtBot\.venv\Lib\site-packages\httpx\_transports\default.py", line 393, in handle_async_request
    with map_httpcore_exceptions():
  File "C:\Users\38066\AppData\Local\Programs\Python\Python312\Lib\contextlib.py", line 158, in __exit__
    self.gen.throw(value)
  File "D:\Programming\Python\Supp0rtBot\.venv\Lib\site-packages\httpx\_transports\default.py", line 118, in map_httpcore_exceptions
    raise mapped_exc(message) from exc
httpx.ConnectError: [Errno 11001] getaddrinfo failed

The above exception was the direct cause of the following exception:

Traceback (most recent call last):
  File "D:\Programming\Python\Supp0rtBot\.venv\Lib\site-packages\telegram\ext\_updater.py", line 750, in _network_loop_retry
    if not await do_action():
           ^^^^^^^^^^^^^^^^^
  File "D:\Programming\Python\Supp0rtBot\.venv\Lib\site-packages\telegram\ext\_updater.py", line 744, in do_action
    return action_cb_task.result()
           ^^^^^^^^^^^^^^^^^^^^^^^
  File "C:\Users\38066\AppData\Local\Programs\Python\Python312\Lib\asyncio\futures.py", line 203, in result
    raise self._exception.with_traceback(self._exception_tb)
  File "C:\Users\38066\AppData\Local\Programs\Python\Python312\Lib\asyncio\tasks.py", line 316, in __step_run_and_handle_result
    result = coro.throw(exc)
             ^^^^^^^^^^^^^^^
  File "D:\Programming\Python\Supp0rtBot\.venv\Lib\site-packages\telegram\ext\_updater.py", line 371, in polling_action_cb
    updates = await self.bot.get_updates(
              ^^^^^^^^^^^^^^^^^^^^^^^^^^^
  File "D:\Programming\Python\Supp0rtBot\.venv\Lib\site-packages\telegram\ext\_extbot.py", line 650, in get_updates
    updates = await super().get_updates(
              ^^^^^^^^^^^^^^^^^^^^^^^^^^
  File "D:\Programming\Python\Supp0rtBot\.venv\Lib\site-packages\telegram\_bot.py", line 4480, in get_updates
    await self._post(
  File "D:\Programming\Python\Supp0rtBot\.venv\Lib\site-packages\telegram\_bot.py", line 619, in _post
    return await self._do_post(
           ^^^^^^^^^^^^^^^^^^^^
  File "D:\Programming\Python\Supp0rtBot\.venv\Lib\site-packages\telegram\ext\_extbot.py", line 354, in _do_post
    return await super()._do_post(
           ^^^^^^^^^^^^^^^^^^^^^^^
  File "D:\Programming\Python\Supp0rtBot\.venv\Lib\site-packages\telegram\_bot.py", line 648, in _do_post
    result = await request.post(
             ^^^^^^^^^^^^^^^^^^^
  File "D:\Programming\Python\Supp0rtBot\.venv\Lib\site-packages\telegram\request\_baserequest.py", line 202, in post
    result = await self._request_wrapper(
             ^^^^^^^^^^^^^^^^^^^^^^^^^^^^
  File "D:\Programming\Python\Supp0rtBot\.venv\Lib\site-packages\telegram\request\_baserequest.py", line 334, in _request_wrapper
    code, payload = await self.do_request(
                    ^^^^^^^^^^^^^^^^^^^^^^
  File "D:\Programming\Python\Supp0rtBot\.venv\Lib\site-packages\telegram\request\_httpxrequest.py", line 317, in do_request
    raise NetworkError(f"httpx.{err.__class__.__name__}: {err}") from err
telegram.error.NetworkError: httpx.ConnectError: [Errno 11001] getaddrinfo failed
2025-05-17 23:00:33,430 - telegram.ext.Application - ERROR - No error handlers are registered, logging exception.
Traceback (most recent call last):
  File "D:\Programming\Python\Supp0rtBot\.venv\Lib\site-packages\httpx\_transports\default.py", line 101, in map_httpcore_exceptions
    yield
  File "D:\Programming\Python\Supp0rtBot\.venv\Lib\site-packages\httpx\_transports\default.py", line 394, in handle_async_request
    resp = await self._pool.handle_async_request(req)
           ^^^^^^^^^^^^^^^^^^^^^^^^^^^^^^^^^^^^^^^^^^
  File "D:\Programming\Python\Supp0rtBot\.venv\Lib\site-packages\httpcore\_async\connection_pool.py", line 256, in handle_async_request
    raise exc from None
  File "D:\Programming\Python\Supp0rtBot\.venv\Lib\site-packages\httpcore\_async\connection_pool.py", line 236, in handle_async_request
    response = await connection.handle_async_request(
               ^^^^^^^^^^^^^^^^^^^^^^^^^^^^^^^^^^^^^^
  File "D:\Programming\Python\Supp0rtBot\.venv\Lib\site-packages\httpcore\_async\connection.py", line 101, in handle_async_request
    raise exc
  File "D:\Programming\Python\Supp0rtBot\.venv\Lib\site-packages\httpcore\_async\connection.py", line 78, in handle_async_request
    stream = await self._connect(request)
             ^^^^^^^^^^^^^^^^^^^^^^^^^^^^
  File "D:\Programming\Python\Supp0rtBot\.venv\Lib\site-packages\httpcore\_async\connection.py", line 124, in _connect
    stream = await self._network_backend.connect_tcp(**kwargs)
             ^^^^^^^^^^^^^^^^^^^^^^^^^^^^^^^^^^^^^^^^^^^^^^^^^
  File "D:\Programming\Python\Supp0rtBot\.venv\Lib\site-packages\httpcore\_backends\auto.py", line 31, in connect_tcp
    return await self._backend.connect_tcp(
           ^^^^^^^^^^^^^^^^^^^^^^^^^^^^^^^^
  File "D:\Programming\Python\Supp0rtBot\.venv\Lib\site-packages\httpcore\_backends\anyio.py", line 113, in connect_tcp
    with map_exceptions(exc_map):
  File "C:\Users\38066\AppData\Local\Programs\Python\Python312\Lib\contextlib.py", line 158, in __exit__
    self.gen.throw(value)
  File "D:\Programming\Python\Supp0rtBot\.venv\Lib\site-packages\httpcore\_exceptions.py", line 14, in map_exceptions
    raise to_exc(exc) from exc
httpcore.ConnectError: [Errno 11001] getaddrinfo failed

The above exception was the direct cause of the following exception:

Traceback (most recent call last):
  File "D:\Programming\Python\Supp0rtBot\.venv\Lib\site-packages\telegram\request\_httpxrequest.py", line 293, in do_request
    res = await self._client.request(
          ^^^^^^^^^^^^^^^^^^^^^^^^^^^
  File "D:\Programming\Python\Supp0rtBot\.venv\Lib\site-packages\httpx\_client.py", line 1540, in request
    return await self.send(request, auth=auth, follow_redirects=follow_redirects)
           ^^^^^^^^^^^^^^^^^^^^^^^^^^^^^^^^^^^^^^^^^^^^^^^^^^^^^^^^^^^^^^^^^^^^^^
  File "D:\Programming\Python\Supp0rtBot\.venv\Lib\site-packages\httpx\_client.py", line 1629, in send
    response = await self._send_handling_auth(
               ^^^^^^^^^^^^^^^^^^^^^^^^^^^^^^^
  File "D:\Programming\Python\Supp0rtBot\.venv\Lib\site-packages\httpx\_client.py", line 1657, in _send_handling_auth
    response = await self._send_handling_redirects(
               ^^^^^^^^^^^^^^^^^^^^^^^^^^^^^^^^^^^^
  File "D:\Programming\Python\Supp0rtBot\.venv\Lib\site-packages\httpx\_client.py", line 1694, in _send_handling_redirects
    response = await self._send_single_request(request)
               ^^^^^^^^^^^^^^^^^^^^^^^^^^^^^^^^^^^^^^^^
  File "D:\Programming\Python\Supp0rtBot\.venv\Lib\site-packages\httpx\_client.py", line 1730, in _send_single_request
    response = await transport.handle_async_request(request)
               ^^^^^^^^^^^^^^^^^^^^^^^^^^^^^^^^^^^^^^^^^^^^^
  File "D:\Programming\Python\Supp0rtBot\.venv\Lib\site-packages\httpx\_transports\default.py", line 393, in handle_async_request
    with map_httpcore_exceptions():
  File "C:\Users\38066\AppData\Local\Programs\Python\Python312\Lib\contextlib.py", line 158, in __exit__
    self.gen.throw(value)
  File "D:\Programming\Python\Supp0rtBot\.venv\Lib\site-packages\httpx\_transports\default.py", line 118, in map_httpcore_exceptions
    raise mapped_exc(message) from exc
httpx.ConnectError: [Errno 11001] getaddrinfo failed

The above exception was the direct cause of the following exception:

Traceback (most recent call last):
  File "D:\Programming\Python\Supp0rtBot\.venv\Lib\site-packages\telegram\ext\_updater.py", line 750, in _network_loop_retry
    if not await do_action():
           ^^^^^^^^^^^^^^^^^
  File "D:\Programming\Python\Supp0rtBot\.venv\Lib\site-packages\telegram\ext\_updater.py", line 744, in do_action
    return action_cb_task.result()
           ^^^^^^^^^^^^^^^^^^^^^^^
  File "C:\Users\38066\AppData\Local\Programs\Python\Python312\Lib\asyncio\futures.py", line 203, in result
    raise self._exception.with_traceback(self._exception_tb)
  File "C:\Users\38066\AppData\Local\Programs\Python\Python312\Lib\asyncio\tasks.py", line 316, in __step_run_and_handle_result
    result = coro.throw(exc)
             ^^^^^^^^^^^^^^^
  File "D:\Programming\Python\Supp0rtBot\.venv\Lib\site-packages\telegram\ext\_updater.py", line 371, in polling_action_cb
    updates = await self.bot.get_updates(
              ^^^^^^^^^^^^^^^^^^^^^^^^^^^
  File "D:\Programming\Python\Supp0rtBot\.venv\Lib\site-packages\telegram\ext\_extbot.py", line 650, in get_updates
    updates = await super().get_updates(
              ^^^^^^^^^^^^^^^^^^^^^^^^^^
  File "D:\Programming\Python\Supp0rtBot\.venv\Lib\site-packages\telegram\_bot.py", line 4480, in get_updates
    await self._post(
  File "D:\Programming\Python\Supp0rtBot\.venv\Lib\site-packages\telegram\_bot.py", line 619, in _post
    return await self._do_post(
           ^^^^^^^^^^^^^^^^^^^^
  File "D:\Programming\Python\Supp0rtBot\.venv\Lib\site-packages\telegram\ext\_extbot.py", line 354, in _do_post
    return await super()._do_post(
           ^^^^^^^^^^^^^^^^^^^^^^^
  File "D:\Programming\Python\Supp0rtBot\.venv\Lib\site-packages\telegram\_bot.py", line 648, in _do_post
    result = await request.post(
             ^^^^^^^^^^^^^^^^^^^
  File "D:\Programming\Python\Supp0rtBot\.venv\Lib\site-packages\telegram\request\_baserequest.py", line 202, in post
    result = await self._request_wrapper(
             ^^^^^^^^^^^^^^^^^^^^^^^^^^^^
  File "D:\Programming\Python\Supp0rtBot\.venv\Lib\site-packages\telegram\request\_baserequest.py", line 334, in _request_wrapper
    code, payload = await self.do_request(
                    ^^^^^^^^^^^^^^^^^^^^^^
  File "D:\Programming\Python\Supp0rtBot\.venv\Lib\site-packages\telegram\request\_httpxrequest.py", line 317, in do_request
    raise NetworkError(f"httpx.{err.__class__.__name__}: {err}") from err
telegram.error.NetworkError: httpx.ConnectError: [Errno 11001] getaddrinfo failed
2025-05-17 23:00:38,506 - telegram.ext.Application - ERROR - No error handlers are registered, logging exception.
Traceback (most recent call last):
  File "D:\Programming\Python\Supp0rtBot\.venv\Lib\site-packages\httpx\_transports\default.py", line 101, in map_httpcore_exceptions
    yield
  File "D:\Programming\Python\Supp0rtBot\.venv\Lib\site-packages\httpx\_transports\default.py", line 394, in handle_async_request
    resp = await self._pool.handle_async_request(req)
           ^^^^^^^^^^^^^^^^^^^^^^^^^^^^^^^^^^^^^^^^^^
  File "D:\Programming\Python\Supp0rtBot\.venv\Lib\site-packages\httpcore\_async\connection_pool.py", line 256, in handle_async_request
    raise exc from None
  File "D:\Programming\Python\Supp0rtBot\.venv\Lib\site-packages\httpcore\_async\connection_pool.py", line 236, in handle_async_request
    response = await connection.handle_async_request(
               ^^^^^^^^^^^^^^^^^^^^^^^^^^^^^^^^^^^^^^
  File "D:\Programming\Python\Supp0rtBot\.venv\Lib\site-packages\httpcore\_async\connection.py", line 101, in handle_async_request
    raise exc
  File "D:\Programming\Python\Supp0rtBot\.venv\Lib\site-packages\httpcore\_async\connection.py", line 78, in handle_async_request
    stream = await self._connect(request)
             ^^^^^^^^^^^^^^^^^^^^^^^^^^^^
  File "D:\Programming\Python\Supp0rtBot\.venv\Lib\site-packages\httpcore\_async\connection.py", line 124, in _connect
    stream = await self._network_backend.connect_tcp(**kwargs)
             ^^^^^^^^^^^^^^^^^^^^^^^^^^^^^^^^^^^^^^^^^^^^^^^^^
  File "D:\Programming\Python\Supp0rtBot\.venv\Lib\site-packages\httpcore\_backends\auto.py", line 31, in connect_tcp
    return await self._backend.connect_tcp(
           ^^^^^^^^^^^^^^^^^^^^^^^^^^^^^^^^
  File "D:\Programming\Python\Supp0rtBot\.venv\Lib\site-packages\httpcore\_backends\anyio.py", line 113, in connect_tcp
    with map_exceptions(exc_map):
  File "C:\Users\38066\AppData\Local\Programs\Python\Python312\Lib\contextlib.py", line 158, in __exit__
    self.gen.throw(value)
  File "D:\Programming\Python\Supp0rtBot\.venv\Lib\site-packages\httpcore\_exceptions.py", line 14, in map_exceptions
    raise to_exc(exc) from exc
httpcore.ConnectError: [Errno 11001] getaddrinfo failed

The above exception was the direct cause of the following exception:

Traceback (most recent call last):
  File "D:\Programming\Python\Supp0rtBot\.venv\Lib\site-packages\telegram\request\_httpxrequest.py", line 293, in do_request
    res = await self._client.request(
          ^^^^^^^^^^^^^^^^^^^^^^^^^^^
  File "D:\Programming\Python\Supp0rtBot\.venv\Lib\site-packages\httpx\_client.py", line 1540, in request
    return await self.send(request, auth=auth, follow_redirects=follow_redirects)
           ^^^^^^^^^^^^^^^^^^^^^^^^^^^^^^^^^^^^^^^^^^^^^^^^^^^^^^^^^^^^^^^^^^^^^^
  File "D:\Programming\Python\Supp0rtBot\.venv\Lib\site-packages\httpx\_client.py", line 1629, in send
    response = await self._send_handling_auth(
               ^^^^^^^^^^^^^^^^^^^^^^^^^^^^^^^
  File "D:\Programming\Python\Supp0rtBot\.venv\Lib\site-packages\httpx\_client.py", line 1657, in _send_handling_auth
    response = await self._send_handling_redirects(
               ^^^^^^^^^^^^^^^^^^^^^^^^^^^^^^^^^^^^
  File "D:\Programming\Python\Supp0rtBot\.venv\Lib\site-packages\httpx\_client.py", line 1694, in _send_handling_redirects
    response = await self._send_single_request(request)
               ^^^^^^^^^^^^^^^^^^^^^^^^^^^^^^^^^^^^^^^^
  File "D:\Programming\Python\Supp0rtBot\.venv\Lib\site-packages\httpx\_client.py", line 1730, in _send_single_request
    response = await transport.handle_async_request(request)
               ^^^^^^^^^^^^^^^^^^^^^^^^^^^^^^^^^^^^^^^^^^^^^
  File "D:\Programming\Python\Supp0rtBot\.venv\Lib\site-packages\httpx\_transports\default.py", line 393, in handle_async_request
    with map_httpcore_exceptions():
  File "C:\Users\38066\AppData\Local\Programs\Python\Python312\Lib\contextlib.py", line 158, in __exit__
    self.gen.throw(value)
  File "D:\Programming\Python\Supp0rtBot\.venv\Lib\site-packages\httpx\_transports\default.py", line 118, in map_httpcore_exceptions
    raise mapped_exc(message) from exc
httpx.ConnectError: [Errno 11001] getaddrinfo failed

The above exception was the direct cause of the following exception:

Traceback (most recent call last):
  File "D:\Programming\Python\Supp0rtBot\.venv\Lib\site-packages\telegram\ext\_updater.py", line 750, in _network_loop_retry
    if not await do_action():
           ^^^^^^^^^^^^^^^^^
  File "D:\Programming\Python\Supp0rtBot\.venv\Lib\site-packages\telegram\ext\_updater.py", line 744, in do_action
    return action_cb_task.result()
           ^^^^^^^^^^^^^^^^^^^^^^^
  File "C:\Users\38066\AppData\Local\Programs\Python\Python312\Lib\asyncio\futures.py", line 203, in result
    raise self._exception.with_traceback(self._exception_tb)
  File "C:\Users\38066\AppData\Local\Programs\Python\Python312\Lib\asyncio\tasks.py", line 316, in __step_run_and_handle_result
    result = coro.throw(exc)
             ^^^^^^^^^^^^^^^
  File "D:\Programming\Python\Supp0rtBot\.venv\Lib\site-packages\telegram\ext\_updater.py", line 371, in polling_action_cb
    updates = await self.bot.get_updates(
              ^^^^^^^^^^^^^^^^^^^^^^^^^^^
  File "D:\Programming\Python\Supp0rtBot\.venv\Lib\site-packages\telegram\ext\_extbot.py", line 650, in get_updates
    updates = await super().get_updates(
              ^^^^^^^^^^^^^^^^^^^^^^^^^^
  File "D:\Programming\Python\Supp0rtBot\.venv\Lib\site-packages\telegram\_bot.py", line 4480, in get_updates
    await self._post(
  File "D:\Programming\Python\Supp0rtBot\.venv\Lib\site-packages\telegram\_bot.py", line 619, in _post
    return await self._do_post(
           ^^^^^^^^^^^^^^^^^^^^
  File "D:\Programming\Python\Supp0rtBot\.venv\Lib\site-packages\telegram\ext\_extbot.py", line 354, in _do_post
    return await super()._do_post(
           ^^^^^^^^^^^^^^^^^^^^^^^
  File "D:\Programming\Python\Supp0rtBot\.venv\Lib\site-packages\telegram\_bot.py", line 648, in _do_post
    result = await request.post(
             ^^^^^^^^^^^^^^^^^^^
  File "D:\Programming\Python\Supp0rtBot\.venv\Lib\site-packages\telegram\request\_baserequest.py", line 202, in post
    result = await self._request_wrapper(
             ^^^^^^^^^^^^^^^^^^^^^^^^^^^^
  File "D:\Programming\Python\Supp0rtBot\.venv\Lib\site-packages\telegram\request\_baserequest.py", line 334, in _request_wrapper
    code, payload = await self.do_request(
                    ^^^^^^^^^^^^^^^^^^^^^^
  File "D:\Programming\Python\Supp0rtBot\.venv\Lib\site-packages\telegram\request\_httpxrequest.py", line 317, in do_request
    raise NetworkError(f"httpx.{err.__class__.__name__}: {err}") from err
telegram.error.NetworkError: httpx.ConnectError: [Errno 11001] getaddrinfo failed
2025-05-17 23:00:46,107 - telegram.ext.Application - ERROR - No error handlers are registered, logging exception.
Traceback (most recent call last):
  File "D:\Programming\Python\Supp0rtBot\.venv\Lib\site-packages\httpx\_transports\default.py", line 101, in map_httpcore_exceptions
    yield
  File "D:\Programming\Python\Supp0rtBot\.venv\Lib\site-packages\httpx\_transports\default.py", line 394, in handle_async_request
    resp = await self._pool.handle_async_request(req)
           ^^^^^^^^^^^^^^^^^^^^^^^^^^^^^^^^^^^^^^^^^^
  File "D:\Programming\Python\Supp0rtBot\.venv\Lib\site-packages\httpcore\_async\connection_pool.py", line 256, in handle_async_request
    raise exc from None
  File "D:\Programming\Python\Supp0rtBot\.venv\Lib\site-packages\httpcore\_async\connection_pool.py", line 236, in handle_async_request
    response = await connection.handle_async_request(
               ^^^^^^^^^^^^^^^^^^^^^^^^^^^^^^^^^^^^^^
  File "D:\Programming\Python\Supp0rtBot\.venv\Lib\site-packages\httpcore\_async\connection.py", line 101, in handle_async_request
    raise exc
  File "D:\Programming\Python\Supp0rtBot\.venv\Lib\site-packages\httpcore\_async\connection.py", line 78, in handle_async_request
    stream = await self._connect(request)
             ^^^^^^^^^^^^^^^^^^^^^^^^^^^^
  File "D:\Programming\Python\Supp0rtBot\.venv\Lib\site-packages\httpcore\_async\connection.py", line 124, in _connect
    stream = await self._network_backend.connect_tcp(**kwargs)
             ^^^^^^^^^^^^^^^^^^^^^^^^^^^^^^^^^^^^^^^^^^^^^^^^^
  File "D:\Programming\Python\Supp0rtBot\.venv\Lib\site-packages\httpcore\_backends\auto.py", line 31, in connect_tcp
    return await self._backend.connect_tcp(
           ^^^^^^^^^^^^^^^^^^^^^^^^^^^^^^^^
  File "D:\Programming\Python\Supp0rtBot\.venv\Lib\site-packages\httpcore\_backends\anyio.py", line 113, in connect_tcp
    with map_exceptions(exc_map):
  File "C:\Users\38066\AppData\Local\Programs\Python\Python312\Lib\contextlib.py", line 158, in __exit__
    self.gen.throw(value)
  File "D:\Programming\Python\Supp0rtBot\.venv\Lib\site-packages\httpcore\_exceptions.py", line 14, in map_exceptions
    raise to_exc(exc) from exc
httpcore.ConnectError: [Errno 11001] getaddrinfo failed

The above exception was the direct cause of the following exception:

Traceback (most recent call last):
  File "D:\Programming\Python\Supp0rtBot\.venv\Lib\site-packages\telegram\request\_httpxrequest.py", line 293, in do_request
    res = await self._client.request(
          ^^^^^^^^^^^^^^^^^^^^^^^^^^^
  File "D:\Programming\Python\Supp0rtBot\.venv\Lib\site-packages\httpx\_client.py", line 1540, in request
    return await self.send(request, auth=auth, follow_redirects=follow_redirects)
           ^^^^^^^^^^^^^^^^^^^^^^^^^^^^^^^^^^^^^^^^^^^^^^^^^^^^^^^^^^^^^^^^^^^^^^
  File "D:\Programming\Python\Supp0rtBot\.venv\Lib\site-packages\httpx\_client.py", line 1629, in send
    response = await self._send_handling_auth(
               ^^^^^^^^^^^^^^^^^^^^^^^^^^^^^^^
  File "D:\Programming\Python\Supp0rtBot\.venv\Lib\site-packages\httpx\_client.py", line 1657, in _send_handling_auth
    response = await self._send_handling_redirects(
               ^^^^^^^^^^^^^^^^^^^^^^^^^^^^^^^^^^^^
  File "D:\Programming\Python\Supp0rtBot\.venv\Lib\site-packages\httpx\_client.py", line 1694, in _send_handling_redirects
    response = await self._send_single_request(request)
               ^^^^^^^^^^^^^^^^^^^^^^^^^^^^^^^^^^^^^^^^
  File "D:\Programming\Python\Supp0rtBot\.venv\Lib\site-packages\httpx\_client.py", line 1730, in _send_single_request
    response = await transport.handle_async_request(request)
               ^^^^^^^^^^^^^^^^^^^^^^^^^^^^^^^^^^^^^^^^^^^^^
  File "D:\Programming\Python\Supp0rtBot\.venv\Lib\site-packages\httpx\_transports\default.py", line 393, in handle_async_request
    with map_httpcore_exceptions():
  File "C:\Users\38066\AppData\Local\Programs\Python\Python312\Lib\contextlib.py", line 158, in __exit__
    self.gen.throw(value)
  File "D:\Programming\Python\Supp0rtBot\.venv\Lib\site-packages\httpx\_transports\default.py", line 118, in map_httpcore_exceptions
    raise mapped_exc(message) from exc
httpx.ConnectError: [Errno 11001] getaddrinfo failed

The above exception was the direct cause of the following exception:

Traceback (most recent call last):
  File "D:\Programming\Python\Supp0rtBot\.venv\Lib\site-packages\telegram\ext\_updater.py", line 750, in _network_loop_retry
    if not await do_action():
           ^^^^^^^^^^^^^^^^^
  File "D:\Programming\Python\Supp0rtBot\.venv\Lib\site-packages\telegram\ext\_updater.py", line 744, in do_action
    return action_cb_task.result()
           ^^^^^^^^^^^^^^^^^^^^^^^
  File "C:\Users\38066\AppData\Local\Programs\Python\Python312\Lib\asyncio\futures.py", line 203, in result
    raise self._exception.with_traceback(self._exception_tb)
  File "C:\Users\38066\AppData\Local\Programs\Python\Python312\Lib\asyncio\tasks.py", line 316, in __step_run_and_handle_result
    result = coro.throw(exc)
             ^^^^^^^^^^^^^^^
  File "D:\Programming\Python\Supp0rtBot\.venv\Lib\site-packages\telegram\ext\_updater.py", line 371, in polling_action_cb
    updates = await self.bot.get_updates(
              ^^^^^^^^^^^^^^^^^^^^^^^^^^^
  File "D:\Programming\Python\Supp0rtBot\.venv\Lib\site-packages\telegram\ext\_extbot.py", line 650, in get_updates
    updates = await super().get_updates(
              ^^^^^^^^^^^^^^^^^^^^^^^^^^
  File "D:\Programming\Python\Supp0rtBot\.venv\Lib\site-packages\telegram\_bot.py", line 4480, in get_updates
    await self._post(
  File "D:\Programming\Python\Supp0rtBot\.venv\Lib\site-packages\telegram\_bot.py", line 619, in _post
    return await self._do_post(
           ^^^^^^^^^^^^^^^^^^^^
  File "D:\Programming\Python\Supp0rtBot\.venv\Lib\site-packages\telegram\ext\_extbot.py", line 354, in _do_post
    return await super()._do_post(
           ^^^^^^^^^^^^^^^^^^^^^^^
  File "D:\Programming\Python\Supp0rtBot\.venv\Lib\site-packages\telegram\_bot.py", line 648, in _do_post
    result = await request.post(
             ^^^^^^^^^^^^^^^^^^^
  File "D:\Programming\Python\Supp0rtBot\.venv\Lib\site-packages\telegram\request\_baserequest.py", line 202, in post
    result = await self._request_wrapper(
             ^^^^^^^^^^^^^^^^^^^^^^^^^^^^
  File "D:\Programming\Python\Supp0rtBot\.venv\Lib\site-packages\telegram\request\_baserequest.py", line 334, in _request_wrapper
    code, payload = await self.do_request(
                    ^^^^^^^^^^^^^^^^^^^^^^
  File "D:\Programming\Python\Supp0rtBot\.venv\Lib\site-packages\telegram\request\_httpxrequest.py", line 317, in do_request
    raise NetworkError(f"httpx.{err.__class__.__name__}: {err}") from err
telegram.error.NetworkError: httpx.ConnectError: [Errno 11001] getaddrinfo failed
2025-05-17 23:00:57,524 - telegram.ext.Application - ERROR - No error handlers are registered, logging exception.
Traceback (most recent call last):
  File "D:\Programming\Python\Supp0rtBot\.venv\Lib\site-packages\httpx\_transports\default.py", line 101, in map_httpcore_exceptions
    yield
  File "D:\Programming\Python\Supp0rtBot\.venv\Lib\site-packages\httpx\_transports\default.py", line 394, in handle_async_request
    resp = await self._pool.handle_async_request(req)
           ^^^^^^^^^^^^^^^^^^^^^^^^^^^^^^^^^^^^^^^^^^
  File "D:\Programming\Python\Supp0rtBot\.venv\Lib\site-packages\httpcore\_async\connection_pool.py", line 256, in handle_async_request
    raise exc from None
  File "D:\Programming\Python\Supp0rtBot\.venv\Lib\site-packages\httpcore\_async\connection_pool.py", line 236, in handle_async_request
    response = await connection.handle_async_request(
               ^^^^^^^^^^^^^^^^^^^^^^^^^^^^^^^^^^^^^^
  File "D:\Programming\Python\Supp0rtBot\.venv\Lib\site-packages\httpcore\_async\connection.py", line 101, in handle_async_request
    raise exc
  File "D:\Programming\Python\Supp0rtBot\.venv\Lib\site-packages\httpcore\_async\connection.py", line 78, in handle_async_request
    stream = await self._connect(request)
             ^^^^^^^^^^^^^^^^^^^^^^^^^^^^
  File "D:\Programming\Python\Supp0rtBot\.venv\Lib\site-packages\httpcore\_async\connection.py", line 124, in _connect
    stream = await self._network_backend.connect_tcp(**kwargs)
             ^^^^^^^^^^^^^^^^^^^^^^^^^^^^^^^^^^^^^^^^^^^^^^^^^
  File "D:\Programming\Python\Supp0rtBot\.venv\Lib\site-packages\httpcore\_backends\auto.py", line 31, in connect_tcp
    return await self._backend.connect_tcp(
           ^^^^^^^^^^^^^^^^^^^^^^^^^^^^^^^^
  File "D:\Programming\Python\Supp0rtBot\.venv\Lib\site-packages\httpcore\_backends\anyio.py", line 113, in connect_tcp
    with map_exceptions(exc_map):
  File "C:\Users\38066\AppData\Local\Programs\Python\Python312\Lib\contextlib.py", line 158, in __exit__
    self.gen.throw(value)
  File "D:\Programming\Python\Supp0rtBot\.venv\Lib\site-packages\httpcore\_exceptions.py", line 14, in map_exceptions
    raise to_exc(exc) from exc
httpcore.ConnectError: [Errno 11001] getaddrinfo failed

The above exception was the direct cause of the following exception:

Traceback (most recent call last):
  File "D:\Programming\Python\Supp0rtBot\.venv\Lib\site-packages\telegram\request\_httpxrequest.py", line 293, in do_request
    res = await self._client.request(
          ^^^^^^^^^^^^^^^^^^^^^^^^^^^
  File "D:\Programming\Python\Supp0rtBot\.venv\Lib\site-packages\httpx\_client.py", line 1540, in request
    return await self.send(request, auth=auth, follow_redirects=follow_redirects)
           ^^^^^^^^^^^^^^^^^^^^^^^^^^^^^^^^^^^^^^^^^^^^^^^^^^^^^^^^^^^^^^^^^^^^^^
  File "D:\Programming\Python\Supp0rtBot\.venv\Lib\site-packages\httpx\_client.py", line 1629, in send
    response = await self._send_handling_auth(
               ^^^^^^^^^^^^^^^^^^^^^^^^^^^^^^^
  File "D:\Programming\Python\Supp0rtBot\.venv\Lib\site-packages\httpx\_client.py", line 1657, in _send_handling_auth
    response = await self._send_handling_redirects(
               ^^^^^^^^^^^^^^^^^^^^^^^^^^^^^^^^^^^^
  File "D:\Programming\Python\Supp0rtBot\.venv\Lib\site-packages\httpx\_client.py", line 1694, in _send_handling_redirects
    response = await self._send_single_request(request)
               ^^^^^^^^^^^^^^^^^^^^^^^^^^^^^^^^^^^^^^^^
  File "D:\Programming\Python\Supp0rtBot\.venv\Lib\site-packages\httpx\_client.py", line 1730, in _send_single_request
    response = await transport.handle_async_request(request)
               ^^^^^^^^^^^^^^^^^^^^^^^^^^^^^^^^^^^^^^^^^^^^^
  File "D:\Programming\Python\Supp0rtBot\.venv\Lib\site-packages\httpx\_transports\default.py", line 393, in handle_async_request
    with map_httpcore_exceptions():
  File "C:\Users\38066\AppData\Local\Programs\Python\Python312\Lib\contextlib.py", line 158, in __exit__
    self.gen.throw(value)
  File "D:\Programming\Python\Supp0rtBot\.venv\Lib\site-packages\httpx\_transports\default.py", line 118, in map_httpcore_exceptions
    raise mapped_exc(message) from exc
httpx.ConnectError: [Errno 11001] getaddrinfo failed

The above exception was the direct cause of the following exception:

Traceback (most recent call last):
  File "D:\Programming\Python\Supp0rtBot\.venv\Lib\site-packages\telegram\ext\_updater.py", line 750, in _network_loop_retry
    if not await do_action():
           ^^^^^^^^^^^^^^^^^
  File "D:\Programming\Python\Supp0rtBot\.venv\Lib\site-packages\telegram\ext\_updater.py", line 744, in do_action
    return action_cb_task.result()
           ^^^^^^^^^^^^^^^^^^^^^^^
  File "C:\Users\38066\AppData\Local\Programs\Python\Python312\Lib\asyncio\futures.py", line 203, in result
    raise self._exception.with_traceback(self._exception_tb)
  File "C:\Users\38066\AppData\Local\Programs\Python\Python312\Lib\asyncio\tasks.py", line 316, in __step_run_and_handle_result
    result = coro.throw(exc)
             ^^^^^^^^^^^^^^^
  File "D:\Programming\Python\Supp0rtBot\.venv\Lib\site-packages\telegram\ext\_updater.py", line 371, in polling_action_cb
    updates = await self.bot.get_updates(
              ^^^^^^^^^^^^^^^^^^^^^^^^^^^
  File "D:\Programming\Python\Supp0rtBot\.venv\Lib\site-packages\telegram\ext\_extbot.py", line 650, in get_updates
    updates = await super().get_updates(
              ^^^^^^^^^^^^^^^^^^^^^^^^^^
  File "D:\Programming\Python\Supp0rtBot\.venv\Lib\site-packages\telegram\_bot.py", line 4480, in get_updates
    await self._post(
  File "D:\Programming\Python\Supp0rtBot\.venv\Lib\site-packages\telegram\_bot.py", line 619, in _post
    return await self._do_post(
           ^^^^^^^^^^^^^^^^^^^^
  File "D:\Programming\Python\Supp0rtBot\.venv\Lib\site-packages\telegram\ext\_extbot.py", line 354, in _do_post
    return await super()._do_post(
           ^^^^^^^^^^^^^^^^^^^^^^^
  File "D:\Programming\Python\Supp0rtBot\.venv\Lib\site-packages\telegram\_bot.py", line 648, in _do_post
    result = await request.post(
             ^^^^^^^^^^^^^^^^^^^
  File "D:\Programming\Python\Supp0rtBot\.venv\Lib\site-packages\telegram\request\_baserequest.py", line 202, in post
    result = await self._request_wrapper(
             ^^^^^^^^^^^^^^^^^^^^^^^^^^^^
  File "D:\Programming\Python\Supp0rtBot\.venv\Lib\site-packages\telegram\request\_baserequest.py", line 334, in _request_wrapper
    code, payload = await self.do_request(
                    ^^^^^^^^^^^^^^^^^^^^^^
  File "D:\Programming\Python\Supp0rtBot\.venv\Lib\site-packages\telegram\request\_httpxrequest.py", line 317, in do_request
    raise NetworkError(f"httpx.{err.__class__.__name__}: {err}") from err
telegram.error.NetworkError: httpx.ConnectError: [Errno 11001] getaddrinfo failed
2025-05-17 23:01:14,617 - telegram.ext.Application - ERROR - No error handlers are registered, logging exception.
Traceback (most recent call last):
  File "D:\Programming\Python\Supp0rtBot\.venv\Lib\site-packages\httpx\_transports\default.py", line 101, in map_httpcore_exceptions
    yield
  File "D:\Programming\Python\Supp0rtBot\.venv\Lib\site-packages\httpx\_transports\default.py", line 394, in handle_async_request
    resp = await self._pool.handle_async_request(req)
           ^^^^^^^^^^^^^^^^^^^^^^^^^^^^^^^^^^^^^^^^^^
  File "D:\Programming\Python\Supp0rtBot\.venv\Lib\site-packages\httpcore\_async\connection_pool.py", line 256, in handle_async_request
    raise exc from None
  File "D:\Programming\Python\Supp0rtBot\.venv\Lib\site-packages\httpcore\_async\connection_pool.py", line 236, in handle_async_request
    response = await connection.handle_async_request(
               ^^^^^^^^^^^^^^^^^^^^^^^^^^^^^^^^^^^^^^
  File "D:\Programming\Python\Supp0rtBot\.venv\Lib\site-packages\httpcore\_async\connection.py", line 101, in handle_async_request
    raise exc
  File "D:\Programming\Python\Supp0rtBot\.venv\Lib\site-packages\httpcore\_async\connection.py", line 78, in handle_async_request
    stream = await self._connect(request)
             ^^^^^^^^^^^^^^^^^^^^^^^^^^^^
  File "D:\Programming\Python\Supp0rtBot\.venv\Lib\site-packages\httpcore\_async\connection.py", line 124, in _connect
    stream = await self._network_backend.connect_tcp(**kwargs)
             ^^^^^^^^^^^^^^^^^^^^^^^^^^^^^^^^^^^^^^^^^^^^^^^^^
  File "D:\Programming\Python\Supp0rtBot\.venv\Lib\site-packages\httpcore\_backends\auto.py", line 31, in connect_tcp
    return await self._backend.connect_tcp(
           ^^^^^^^^^^^^^^^^^^^^^^^^^^^^^^^^
  File "D:\Programming\Python\Supp0rtBot\.venv\Lib\site-packages\httpcore\_backends\anyio.py", line 113, in connect_tcp
    with map_exceptions(exc_map):
  File "C:\Users\38066\AppData\Local\Programs\Python\Python312\Lib\contextlib.py", line 158, in __exit__
    self.gen.throw(value)
  File "D:\Programming\Python\Supp0rtBot\.venv\Lib\site-packages\httpcore\_exceptions.py", line 14, in map_exceptions
    raise to_exc(exc) from exc
httpcore.ConnectError: [Errno 11001] getaddrinfo failed

The above exception was the direct cause of the following exception:

Traceback (most recent call last):
  File "D:\Programming\Python\Supp0rtBot\.venv\Lib\site-packages\telegram\request\_httpxrequest.py", line 293, in do_request
    res = await self._client.request(
          ^^^^^^^^^^^^^^^^^^^^^^^^^^^
  File "D:\Programming\Python\Supp0rtBot\.venv\Lib\site-packages\httpx\_client.py", line 1540, in request
    return await self.send(request, auth=auth, follow_redirects=follow_redirects)
           ^^^^^^^^^^^^^^^^^^^^^^^^^^^^^^^^^^^^^^^^^^^^^^^^^^^^^^^^^^^^^^^^^^^^^^
  File "D:\Programming\Python\Supp0rtBot\.venv\Lib\site-packages\httpx\_client.py", line 1629, in send
    response = await self._send_handling_auth(
               ^^^^^^^^^^^^^^^^^^^^^^^^^^^^^^^
  File "D:\Programming\Python\Supp0rtBot\.venv\Lib\site-packages\httpx\_client.py", line 1657, in _send_handling_auth
    response = await self._send_handling_redirects(
               ^^^^^^^^^^^^^^^^^^^^^^^^^^^^^^^^^^^^
  File "D:\Programming\Python\Supp0rtBot\.venv\Lib\site-packages\httpx\_client.py", line 1694, in _send_handling_redirects
    response = await self._send_single_request(request)
               ^^^^^^^^^^^^^^^^^^^^^^^^^^^^^^^^^^^^^^^^
  File "D:\Programming\Python\Supp0rtBot\.venv\Lib\site-packages\httpx\_client.py", line 1730, in _send_single_request
    response = await transport.handle_async_request(request)
               ^^^^^^^^^^^^^^^^^^^^^^^^^^^^^^^^^^^^^^^^^^^^^
  File "D:\Programming\Python\Supp0rtBot\.venv\Lib\site-packages\httpx\_transports\default.py", line 393, in handle_async_request
    with map_httpcore_exceptions():
  File "C:\Users\38066\AppData\Local\Programs\Python\Python312\Lib\contextlib.py", line 158, in __exit__
    self.gen.throw(value)
  File "D:\Programming\Python\Supp0rtBot\.venv\Lib\site-packages\httpx\_transports\default.py", line 118, in map_httpcore_exceptions
    raise mapped_exc(message) from exc
httpx.ConnectError: [Errno 11001] getaddrinfo failed

The above exception was the direct cause of the following exception:

Traceback (most recent call last):
  File "D:\Programming\Python\Supp0rtBot\.venv\Lib\site-packages\telegram\ext\_updater.py", line 750, in _network_loop_retry
    if not await do_action():
           ^^^^^^^^^^^^^^^^^
  File "D:\Programming\Python\Supp0rtBot\.venv\Lib\site-packages\telegram\ext\_updater.py", line 744, in do_action
    return action_cb_task.result()
           ^^^^^^^^^^^^^^^^^^^^^^^
  File "C:\Users\38066\AppData\Local\Programs\Python\Python312\Lib\asyncio\futures.py", line 203, in result
    raise self._exception.with_traceback(self._exception_tb)
  File "C:\Users\38066\AppData\Local\Programs\Python\Python312\Lib\asyncio\tasks.py", line 316, in __step_run_and_handle_result
    result = coro.throw(exc)
             ^^^^^^^^^^^^^^^
  File "D:\Programming\Python\Supp0rtBot\.venv\Lib\site-packages\telegram\ext\_updater.py", line 371, in polling_action_cb
    updates = await self.bot.get_updates(
              ^^^^^^^^^^^^^^^^^^^^^^^^^^^
  File "D:\Programming\Python\Supp0rtBot\.venv\Lib\site-packages\telegram\ext\_extbot.py", line 650, in get_updates
    updates = await super().get_updates(
              ^^^^^^^^^^^^^^^^^^^^^^^^^^
  File "D:\Programming\Python\Supp0rtBot\.venv\Lib\site-packages\telegram\_bot.py", line 4480, in get_updates
    await self._post(
  File "D:\Programming\Python\Supp0rtBot\.venv\Lib\site-packages\telegram\_bot.py", line 619, in _post
    return await self._do_post(
           ^^^^^^^^^^^^^^^^^^^^
  File "D:\Programming\Python\Supp0rtBot\.venv\Lib\site-packages\telegram\ext\_extbot.py", line 354, in _do_post
    return await super()._do_post(
           ^^^^^^^^^^^^^^^^^^^^^^^
  File "D:\Programming\Python\Supp0rtBot\.venv\Lib\site-packages\telegram\_bot.py", line 648, in _do_post
    result = await request.post(
             ^^^^^^^^^^^^^^^^^^^
  File "D:\Programming\Python\Supp0rtBot\.venv\Lib\site-packages\telegram\request\_baserequest.py", line 202, in post
    result = await self._request_wrapper(
             ^^^^^^^^^^^^^^^^^^^^^^^^^^^^
  File "D:\Programming\Python\Supp0rtBot\.venv\Lib\site-packages\telegram\request\_baserequest.py", line 334, in _request_wrapper
    code, payload = await self.do_request(
                    ^^^^^^^^^^^^^^^^^^^^^^
  File "D:\Programming\Python\Supp0rtBot\.venv\Lib\site-packages\telegram\request\_httpxrequest.py", line 317, in do_request
    raise NetworkError(f"httpx.{err.__class__.__name__}: {err}") from err
telegram.error.NetworkError: httpx.ConnectError: [Errno 11001] getaddrinfo failed
2025-05-17 23:04:54,885 - werkzeug - INFO - [31m[1mWARNING: This is a development server. Do not use it in a production deployment. Use a production WSGI server instead.[0m
 * Running on all addresses (0.0.0.0)
 * Running on http://127.0.0.1:5000
 * Running on http://192.168.31.105:5000
2025-05-17 23:04:54,885 - werkzeug - INFO - [33mPress CTRL+C to quit[0m
2025-05-17 23:20:14,027 - werkzeug - INFO - [31m[1mWARNING: This is a development server. Do not use it in a production deployment. Use a production WSGI server instead.[0m
 * Running on all addresses (0.0.0.0)
 * Running on http://127.0.0.1:5000
 * Running on http://192.168.31.105:5000
2025-05-17 23:20:14,027 - werkzeug - INFO - [33mPress CTRL+C to quit[0m
2025-05-17 23:22:42,557 - werkzeug - INFO - [31m[1mWARNING: This is a development server. Do not use it in a production deployment. Use a production WSGI server instead.[0m
 * Running on all addresses (0.0.0.0)
 * Running on http://127.0.0.1:5000
 * Running on http://192.168.31.105:5000
2025-05-17 23:22:42,557 - werkzeug - INFO - [33mPress CTRL+C to quit[0m
